Workbook

Sheet Max_An_non_triee
D1: PDT min | F1: 5 | H1: 15 | J1: 30 | L1: 60 | N1: 180 | P1: 360
D2: PDT titre | E2: r1 | G2: r10 | I2: r2 | K2: r3 | M2: r4 | O2: r5
E4: année | F4: RR | G4: année | H4: RR | I4: année | J4: RR | K4: année | L4: RR | M4: année | N4: RR | O4: année | P4: RR
F5: [mm] | H5: [mm] | J5: [mm] | L5: [mm] | N5: [mm] | P5: [mm]
E7: 1995 | F7: 48.113587 | G7: 1995 | H7: 158.38677 | I7: 1995 | J7: 53.177466 | K7: 1995 | L7: 35.342662 | M7: 1995 | N7: 51.343814 | O7: 1995 | P7: 67.887197
E8: 1996 | F8: 55.202284 | G8: 1996 | H8: 45.677841 | I8: 1996 | J8: 48.409488 | K8: 1996 | L8: 67.232444 | M8: 1996 | N8: 69.970812 | O8: 1996 | P8: 64.492448
E9: 1997 | F9: 85.479384 | G9: 1997 | H9: 55.149309 | I9: 1997 | J9: 60.713037 | K9: 1997 | L9: 63.557696 | M9: 1997 | N9: 109.63915 | O9: 1997 | P9: 48.779421
E10: 1998 | F10: 52.027841 | G10: 1998 | H10: 44.542183 | I10: 1998 | J10: 48.725679 | K10: 1998 | L10: 68.347725 | M10: 1998 | N10: 50.365691 | O10: 1998 | P10: 31.750242
E11: 1999 | F11: 71.92118 | G11: 1999 | H11: 47.69377 | I11: 1999 | J11: 58.509511 | K11: 1999 | L11: 53.175628 | M11: 1999 | N11: 37.6056 | O11: 1999 | P11: 62.855809
E12: 2000 | F12: 42.9274 | G12: 2000 | H12: 31.716584 | I12: 2000 | J12: 75.779616 | K12: 2000 | L12: 174.136 | M12: 2000 | N12: 124.62002 | O12: 2000 | P12: 46.8602
E13: 2001 | F13: 32.869201 | G13: 2001 | H13: 130.40716 | I13: 2001 | J13: 46.90432 | K13: 2001 | L13: 49.235622 | M13: 2001 | N13: 49.904619 | O13: 2001 | P13: 47.69377
E14: 2002 | F14: 48.386913 | G14: 2002 | H14: 53.529602 | I14: 2002 | J14: 46.322729 | K14: 2002 | L14: 64.341592 | M14: 2002 | N14: 180.25959 | O14: 2002 | P14: 130.40716
E15: 2003 | F15: 73.686025 | G15: 2003 | H15: 50.334666 | I15: 2003 | J15: 42.571262 | K15: 2003 | L15: 122.45557 | M15: 2003 | N15: 42.456314 | O15: 2003 | P15: 74.596848
E16: 2004 | F16: 79.012511 | G16: 2004 | H16: 130.14036 | I16: 2004 | J16: 130.32176 | K16: 2004 | L16: 79.541658 | M16: 2004 | N16: 54.546707 | O16: 2004 | P16: 180.25959
E17: 2005 | F17: 145.2444 | G17: 2005 | H17: 45.203563 | I17: 2005 | J17: 53.300994 | K17: 2005 | L17: 108.04607 | M17: 2005 | N17: 69.16986 | O17: 2005 | P17: 31.834221
E18: 2006 | F18: 68.347725 | G18: 2006 | H18: 61.421307 | I18: 2006 | J18: 65.493967 | K18: 2006 | L18: 46.103955 | M18: 2006 | N18: 116.9131 | O18: 2006 | P18: 71.749006
... E26: 2014 | F26: 50.704898 | G26: 2014 | H26: 81.782529 | I26: 2014 | J26: 148.15862 | K26: 2014 | L26: 178.83379 | M26: 2014 | N26: 44.353999 | O26: 2014 | P26: 64.768308

Sheet Valeurs Maximales Annuelles
C2: Coefficient de Weiss: | E2: =Max_An_non_triee!E2 -> r1 | G2: =Max_An_non_triee!G2 -> r10 | I2: =Max_An_non_triee!I2 -> r2 | K2: =Max_An_non_triee!K2 -> r3 | M2: =Max_An_non_triee!M2 -> r4 | O2: 6h
C3: 1
E4: RR tri | F4: Weiss | G4: RR tri | H4: Weiss | I4: RR tri | J4: Weiss | K4: RR tri | L4: Weiss | M4: RR tri | N4: Weiss | O4: RR tri | P4: Weiss
E5: [mm] | G5: [mm] | I5: [mm] | K5: [mm] | M5: [mm] | O5: [mm]
E7: {=_xlfn._xlws.SORT(Max_An_non_triee!F7:F1000,,1,FALSE)} -> 26.361987 | F7: =E7*$C$3 -> 26.361987 | G7: {=_xlfn._xlws.SORT(Max_An_non_triee!H7:H1000,,1,FALSE)} -> 31.716584 | H7: =G7*$C$3 -> 31.716584 | I7: {=_xlfn._xlws.SORT(Max_An_non_triee!J7:J1000,,1,FALSE)} -> 39.533421 | J7: =I7*$C$3 -> 39.533421 | K7: {=_xlfn._xlws.SORT(Max_An_non_triee!L7:L1000,,1,FALSE)} -> 32.911838 | L7: =K7*$C$3 -> 32.911838 | M7: {=_xlfn._xlws.SORT(Max_An_non_triee!N7:N1000,,1,FALSE)} -> 34.613623 | N7: =M7*$C$3 -> 34.613623 | O7: {=_xlfn._xlws.SORT(Max_An_non_triee!P7:P1000,,1,FALSE)} -> 31.750242 | P7: =O7*$C$3 -> 31.750242
E8: 32.869201 | F8: =E8*$C$3 -> 32.869201 | G8: 42.476169 | H8: =G8*$C$3 -> 42.476169 | I8: 42.571262 | J8: =I8*$C$3 -> 42.571262 | K8: 35.342662 | L8: =K8*$C$3 -> 35.342662 | M8: 37.6056 | N8: =M8*$C$3 -> 37.6056 | O8: 31.834221 | P8: =O8*$C$3 -> 31.834221
E9: 42.9274 | F9: =E9*$C$3 -> 42.9274 | G9: 44.542183 | H9: =G9*$C$3 -> 44.542183 | I9: 42.932035 | J9: =I9*$C$3 -> 42.932035 | K9: 39.48864 | L9: =K9*$C$3 -> 39.48864 | M9: 42.456314 | N9: =M9*$C$3 -> 42.456314 | O9: 42.103696 | P9: =O9*$C$3 -> 42.103696
E10: 47.048988 | F10: =E10*$C$3 -> 47.048988 | G10: 45.203563 | H10: =G10*$C$3 -> 45.203563 | I10: 46.322729 | J10: =I10*$C$3 -> 46.322729 | K10: 46.103955 | L10: =K10*$C$3 -> 46.103955 | M10: 44.353999 | N10: =M10*$C$3 -> 44.353999 | O10: 46.8602 | P10: =O10*$C$3 -> 46.8602
E11: 48.113587 | F11: =E11*$C$3 -> 48.113587 | G11: 45.677841 | H11: =G11*$C$3 -> 45.677841 | I11: 46.428178 | J11: =I11*$C$3 -> 46.428178 | K11: 47.186495 | L11: =K11*$C$3 -> 47.186495 | M11: 46.757559 | N11: =M11*$C$3 -> 46.757559 | O11: 47.69377 | P11: =O11*$C$3 -> 47.69377
E12: 48.386913 | F12: =E12*$C$3 -> 48.386913 | G12: 47.69377 | H12: =G12*$C$3 -> 47.69377 | I12: 46.90432 | J12: =I12*$C$3 -> 46.90432 | K12: 48.560495 | L12: =K12*$C$3 -> 48.560495 | M12: 49.904619 | N12: =M12*$C$3 -> 49.904619 | O12: 48.779421 | P12: =O12*$C$3 -> 48.779421
E13: 50.666395 | F13: =E13*$C$3 -> 50.666395 | G13: 50.334666 | H13: =G13*$C$3 -> 50.334666 | I13: 48.409488 | J13: =I13*$C$3 -> 48.409488 | K13: 49.235622 | L13: =K13*$C$3 -> 49.235622 | M13: 50.365691 | N13: =M13*$C$3 -> 50.365691 | O13: 52.934498 | P13: =O13*$C$3 -> 52.934498
E14: 50.704898 | F14: =E14*$C$3 -> 50.704898 | G14: 53.529602 | H14: =G14*$C$3 -> 53.529602 | I14: 48.725679 | J14: =I14*$C$3 -> 48.725679 | K14: 53.175628 | L14: =K14*$C$3 -> 53.175628 | M14: 51.343814 | N14: =M14*$C$3 -> 51.343814 | O14: 54.546707 | P14: =O14*$C$3 -> 54.546707
E15: 52.027841 | F15: =E15*$C$3 -> 52.027841 | G15: 53.938448 | H15: =G15*$C$3 -> 53.938448 | I15: 53.177466 | J15: =I15*$C$3 -> 53.177466 | K15: 57.815447 | L15: =K15*$C$3 -> 57.815447 | M15: 54.546707 | N15: =M15*$C$3 -> 54.546707 | O15: 60.656313 | P15: =O15*$C$3 -> 60.656313
E16: 53.786801 | F16: =E16*$C$3 -> 53.786801 | G16: 55.149309 | H16: =G16*$C$3 -> 55.149309 | I16: 53.300994 | J16: =I16*$C$3 -> 53.300994 | K16: 58.036922 | L16: =K16*$C$3 -> 58.036922 | M16: 55.72396 | N16: =M16*$C$3 -> 55.72396 | O16: 62.855809 | P16: =O16*$C$3 -> 62.855809
E17: 55.202284 | F17: =E17*$C$3 -> 55.202284 | G17: 58.186632 | H17: =G17*$C$3 -> 58.186632 | I17: 58.509511 | J17: =I17*$C$3 -> 58.509511 | K17: 63.557696 | L17: =K17*$C$3 -> 63.557696 | M17: 65.458561 | N17: =M17*$C$3 -> 65.458561 | O17: 64.492448 | P17: =O17*$C$3 -> 64.492448
E18: 68.347725 | F18: =E18*$C$3 -> 68.347725 | G18: 58.467666 | H18: =G18*$C$3 -> 58.467666 | I18: 60.713037 | J18: =I18*$C$3 -> 60.713037 | K18: 64.341592 | L18: =K18*$C$3 -> 64.341592 | M18: 69.16986 | N18: =M18*$C$3 -> 69.16986 | O18: 64.768308 | P18: =O18*$C$3 -> 64.768308
E19: 70.875376 | F19: =E19*$C$3 -> 70.875376 | G19: 61.421307 | H19: =G19*$C$3 -> 61.421307 | I19: 65.493967 | J19: =I19*$C$3 -> 65.493967 | K19: 67.232444 | L19: =K19*$C$3 -> 67.232444 | M19: 69.970812 | N19: =M19*$C$3 -> 69.970812 | O19: 67.887197 | P19: =O19*$C$3 -> 67.887197
... E104: 0 | F104: =E104*$C$3 -> 0 | G104: 0 | H104: =G104*$C$3 -> 0 | I104: 0 | J104: =I104*$C$3 -> 0 | K104: 0 | L104: =K104*$C$3 -> 0 | M104: 0 | N104: =M104*$C$3 -> 0 | O104: 0 | P104: =O104*$C$3 -> 0
E105: 0 | G105: 0 | I105: 0 | K105: 0 | M105: 0 | O105: 0
E106: 0 | G106: 0 | I106: 0 | K106: 0 | M106: 0 | O106: 0
E107: 0 | G107: 0 | I107: 0 | K107: 0 | M107: 0 | O107: 0
E108: 0 | G108: 0 | I108: 0 | K108: 0 | M108: 0 | O108: 0
E109: 0 | G109: 0 | I109: 0 | K109: 0 | M109: 0 | O109: 0
E110: 0 | G110: 0 | I110: 0 | K110: 0 | M110: 0 | O110: 0
E111: 0 | G111: 0 | I111: 0 | K111: 0 | M111: 0 | O111: 0
E112: 0 | G112: 0 | I112: 0 | K112: 0 | M112: 0 | O112: 0
E113: 0 | G113: 0 | I113: 0 | K113: 0 | M113: 0 | O113: 0
E114: 0 | G114: 0 | I114: 0 | K114: 0 | M114: 0 | O114: 0
E115: 0 | G115: 0 | I115: 0 | K115: 0 | M115: 0 | O115: 0
E116: 0 | G116: 0 | I116: 0 | K116: 0 | M116: 0 | O116: 0
... E1000: 0 | G1000: 0 | I1000: 0 | K1000: 0 | M1000: 0 | O1000: 0

Sheet Ajustement de GUMBEL
C1: moyenne = | D1: =AVERAGE(D12:D970) -> 67.419376 | E1: [mm] | P1: moyenne = | Q1: =AVERAGE(Q12:Q970) -> 74.277147 | R1: [mm] | AC1: moyenne = | AD1: =AVERAGE(AD12:AD970) -> 70.086606 | AE1: [mm] | AP1: moyenne = | AQ1: =AVERAGE(AQ12:AQ970) -> 76.23787 | AR1: [mm] | BC1: moyenne = | BD1: =AVERAGE(BD12:BD970) -> 77.308648 | BE1: [mm] | BP1: moyenne = | BQ1: =AVERAGE(BQ12:BQ970) -> 76.199023 | BR1: [mm]
C2: variance = | D2: =VAR(D12:D970) -> 979.60794 | E2: [-] | P2: variance = | Q2: =VAR(Q12:Q970) -> 1751.5768 | R2: [-] | AC2: variance = | AD2: =VAR(AD12:AD970) -> 1104.8699 | AE2: [-] | AP2: variance = | AQ2: =VAR(AQ12:AQ970) -> 1894.6568 | AR2: [-] | BC2: variance = | BD2: =VAR(BD12:BD970) -> 1687.0958 | BE2: [-] | BP2: variance = | BQ2: =VAR(BQ12:BQ970) -> 1858.5985 | BR2: [-]
C4: paramètre b = | D4: =SQRT(6/PI()^2*D2) -> 24.403488 | E4: [mm] | P4: paramètre b = | Q4: =SQRT(6/PI()^2*Q2) -> 32.631749 | R4: [mm] | AC4: paramètre b = | AD4: =SQRT(6/PI()^2*AD2) -> 25.916797 | AE4: [mm] | AP4: paramètre b = | AQ4: =SQRT(6/PI()^2*AQ2) -> 33.938374 | AR4: [mm] | BC4: paramètre b = | BD4: =SQRT(6/PI()^2*BD2) -> 32.025478 | BE4: [mm] | BP4: paramètre b = | BQ4: =SQRT(6/PI()^2*BQ2) -> 33.613873 | BR4: [mm]
C5: paramètre a = | D5: =D1-D4*0.5772156649 -> 53.3333 | E5: [mm] | P5: paramètre a = | Q5: =Q1-Q4*0.5772156649 -> 55.441591 | R5: [mm] | AC5: paramètre a = | AD5: =AD1-AD4*0.5772156649 -> 55.127024 | AE5: [mm] | AP5: paramètre a = | AQ5: =AQ1-AQ4*0.5772156649 -> 56.648109 | AR5: [mm] | BC5: paramètre a = | BD5: =BD1-BD4*0.5772156649 -> 58.823041 | BE5: [mm] | BP5: paramètre a = | BQ5: =BQ1-BQ4*0.5772156649 -> 56.796569 | BR5: [mm]
D7: =Max_An_non_triee!E2 -> r1 | Q7: =Max_An_non_triee!G2 -> r10 | AD7: =Max_An_non_triee!I2 -> r2 | AQ7: =Max_An_non_triee!K2 -> r3 | BD7: =Max_An_non_triee!M2 -> r4 | BQ7: =Max_An_non_triee!O2 -> r5 | BR7: teste
C8: N= | D8: =COUNT(D12:D970) -> 20 | P8: N= | Q8: =COUNT(Q12:Q970) -> 20 | AC8: N= | AD8: =COUNT(AD12:AD970) -> 20 | AP8: N= | AQ8: =COUNT(AQ12:AQ970) -> 20 | BC8: N= | BD8: =COUNT(BD12:BD970) -> 20 | BP8: N= | BQ8: =COUNT(BQ12:BQ970) -> 20
A9: rang | B9: fréquence empirique de Hazen | C9: variable réduite de Gumbel | D9: =_xlfn.CONCAT(D7,"_obs") -> r1_obs | E9: =_xlfn.CONCAT(D7,"_ajust") -> r1_ajust | N9: rang | O9: fréquence empirique de Hazen | P9: variable réduite de Gumbel | Q9: =_xlfn.CONCAT(Q7,"_obs") -> r10_obs | R9: =_xlfn.CONCAT(Q7,"_ajust") -> r10_ajust | AA9: rang | AB9: fréquence empirique de Hazen | AC9: variable réduite de Gumbel | AD9: =_xlfn.CONCAT(AD7,"_obs") -> r2_obs | AE9: =_xlfn.CONCAT(AD7,"_ajust") -> r2_ajust | AN9: rang | AO9: fréquence empirique de Hazen | AP9: variable réduite de Gumbel | AQ9: =_xlfn.CONCAT(AQ7,"_obs") -> r3_obs | AR9: =_xlfn.CONCAT(AQ7,"_ajust") -> r3_ajust | BA9: rang | BB9: fréquence empirique de Hazen | BC9: variable réduite de Gumbel | BD9: =_xlfn.CONCAT(BD7,"_obs") -> r4_obs | BE9: =_xlfn.CONCAT(BD7,"_ajust") -> r4_ajust | BN9: rang | BO9: fréquence empirique de Hazen | BP9: variable réduite de Gumbel | BQ9: =_xlfn.CONCAT(BQ7,"_obs") -> r5_obs | BR9: =_xlfn.CONCAT(BQ7,"_ajust") -> r5_ajust
A10: [-] | B10: [-] | C10: [-] | D10: [mm] | E10: [mm] | F10: Intervalle de confiance à 95% | N10: [-] | O10: [-] | P10: [-] | Q10: [mm] | R10: [mm] | S10: Intervalle de confiance à 95% | AA10: [-] | AB10: [-] | AC10: [-] | AD10: [mm] | AE10: [mm] | AF10: Intervalle de confiance à 95% | AN10: [-] | AO10: [-] | AP10: [-] | AQ10: [mm] | AR10: [mm] | AS10: Intervalle de confiance à 95% | BA10: [-] | BB10: [-] | BC10: [-] | BD10: [mm] | BE10: [mm] | BF10: Intervalle de confiance à 95% | BN10: [-] | BO10: [-] | BP10: [-] | BQ10: [mm] | BR10: [mm] | BS10: Intervalle de confiance à 95%
F11: TR | G11: F | H11: H max | I11: u | J11: =_xlfn.CONCAT("5%_",D7) -> 5%_r1 | K11: =_xlfn.CONCAT("95%_",D7) -> 95%_r1 | L11: σQJM | S11: TR | T11: F | U11: H max | V11: u | W11: =_xlfn.CONCAT("5%_",Q7) -> 5%_r10 | X11: =_xlfn.CONCAT("95%_",Q7) -> 95%_r10 | Y11: σQJM | AF11: TR | AG11: F | AH11: H max | AI11: u | AJ11: =_xlfn.CONCAT("5%_",AD7) -> 5%_r2 | AK11: =_xlfn.CONCAT("95%_",AD7) -> 95%_r2 | AL11: σQJM | AS11: TR | AT11: F | AU11: H max | AV11: u | AW11: =_xlfn.CONCAT("5%_",AQ7) -> 5%_r3 | AX11: =_xlfn.CONCAT("95%_",AQ7) -> 95%_r3 | AY11: σQJM | BF11: TR | BG11: F | BH11: H max | BI11: u | BJ11: =_xlfn.CONCAT("5%_",BD7) -> 5%_r4 | BK11: =_xlfn.CONCAT("95%_",BD7) -> 95%_r4 | BL11: σQJM | BQ11: Obs | BR11: Ajust | BS11: TR | BT11: F | BU11: H max | BV11: u | BW11: =_xlfn.CONCAT("5%_",BQ7) -> 5%_r5 | BX11: =_xlfn.CONCAT("95%_",BQ7) -> 95%_r5 | BY11: σQJM
A12: =RANK(D12,D$12:D$970,1) -> 1 | B12: =(A12-0.5)/COUNT(A$12:A$970) -> 0.025 | C12: =-LN(-LN(B12)) -> -1.3053227 | D12: ='Valeurs Maximales Annuelles'!F7 -> 26.361987 | E12: =D$5+C12*D$4 -> 21.478873 | F12: =1/(1-G12) -> 1.010101 | G12: 0.01 | H12: =D$5-D$4*LN(-LN(G12)) -> 16.064791 | I12: =-LN(-LN(G12)) -> -1.5271796 | J12: =H12-L12*1.96 -> -4.2888641 | K12: =H12+L12*1.96 -> 36.418446 | L12: =(STDEV(D$12:D$1000)/SQRT(D$8-1))*SQRT(0.7099+0.1165*I12+0.6687*I12*I12) -> 10.384518 | N12: =RANK(Q12,Q$12:Q$970,1) -> 1 | O12: =(N12-0.5)/COUNT(N$12:N$970) -> 0.025 | P12: =-LN(-LN(O12)) -> -1.3053227 | Q12: ='Valeurs Maximales Annuelles'!H7 -> 31.716584 | R12: =Q$5+P12*Q$4 -> 12.846627 | S12: =1/(1-T12) -> 1.010101 | T12: 0.01 | U12: =Q$5-Q$4*LN(-LN(T12)) -> 5.6070492 | V12: =-LN(-LN(T12)) -> -1.5271796 | W12: =U12-Y12*1.96 -> -21.609362 | X12: =U12+Y12*1.96 -> 32.82346 | Y12: =(STDEV(Q$12:Q$1000)/SQRT(Q$8-1))*SQRT(0.7099+0.1165*V12+0.6687*V12*V12) -> 13.885924 | AA12: =RANK(AD12,AD$12:AD$970,1) -> 1 | AB12: =(AA12-0.5)/COUNT(AA$12:AA$970) -> 0.025 | AC12: =-LN(-LN(AB12)) -> -1.3053227 | AD12: ='Valeurs Maximales Annuelles'!J7 -> 39.533421 | AE12: =AD$5+AC12*AD$4 -> 21.297239 | AF12: =1/(1-AG12) -> 1.010101 | AG12: 0.01 | AH12: =AD$5-AD$4*LN(-LN(AG12)) -> 15.54742 | AI12: =-LN(-LN(AG12)) -> -1.5271796 | AJ12: =AH12-AL12*1.96 -> -6.0684068 | AK12: =AH12+AL12*1.96 -> 37.163246 | AL12: =(STDEV(AD$12:AD$1000)/SQRT(AD$8-1))*SQRT(0.7099+0.1165*AI12+0.6687*AI12*AI12) -> 11.028483 | AN12: =RANK(AQ12,AQ$12:AQ$970,1) -> 1 | AO12: =(AN12-0.5)/COUNT(AN$12:AN$970) -> 0.025 | AP12: =-LN(-LN(AO12)) -> -1.3053227 | AQ12: ='Valeurs Maximales Annuelles'!L7 -> 32.911838 | AR12: =AQ$5+AP12*AQ$4 -> 12.347577 | AS12: =1/(1-AT12) -> 1.010101 | AT12: 0.01 | AU12: =AQ$5-AQ$4*LN(-LN(AT12)) -> 4.8181154 | AV12: =-LN(-LN(AT12)) -> -1.5271796 | AW12: =AU12-AY12*1.96 -> -23.488083 | AX12: =AU12+AY12*1.96 -> 33.124314 | AY12: =(STDEV(AQ$12:AQ$1000)/SQRT(AQ$8-1))*SQRT(0.7099+0.1165*AV12+0.6687*AV12*AV12) -> 14.441938 | BA12: =RANK(BD12,BD$12:BD$970,1) -> 1 | BB12: =(BA12-0.5)/COUNT(BA$12:BA$970) -> 0.025 | BC12: =-LN(-LN(BB12)) -> -1.3053227 | BD12: ='Valeurs Maximales Annuelles'!N7 -> 34.613623 | BE12: =BD$5+BC12*BD$4 -> 17.019455 | BF12: =1/(1-BG12) -> 1.010101 | BG12: 0.01 | BH12: =BD$5-BD$4*LN(-LN(BG12)) -> 9.9143824 | BI12: =-LN(-LN(BG12)) -> -1.5271796 | BJ12: =BH12-BL12*1.96 -> -16.796371 | BK12: =BH12+BL12*1.96 -> 36.625136 | BL12: =(STDEV(BD$12:BD$1000)/SQRT(BD$8-1))*SQRT(0.7099+0.1165*BI12+0.6687*BI12*BI12) -> 13.627935 | BN12: =RANK(BQ12,BQ$12:BQ$970,1) -> 1 | BO12: =(BN12-0.5)/COUNT(BN$12:BN$970) -> 0.025 | BP12: =-LN(-LN(BO12)) -> -1.3053227 | BQ12: ='Valeurs Maximales Annuelles'!P7 -> 31.750242 | BR12: =BQ$5+BP12*BQ$4 -> 12.919617 | BS12: =1/(1-BT12) -> 1.010101 | BT12: 0.01 | BU12: =BQ$5-BQ$4*LN(-LN(BT12)) -> 5.4621475 | BV12: =-LN(-LN(BT12)) -> -1.5271796 | BW12: =BU12-BY12*1.96 -> -22.573401 | BX12: =BU12+BY12*1.96 -> 33.497696 | BY12: =(STDEV(BQ$12:BQ$1000)/SQRT(BQ$8-1))*SQRT(0.7099+0.1165*BV12+0.6687*BV12*BV12) -> 14.303851
A13: =RANK(D13,D$12:D$970,1) -> 2 | B13: =(A13-0.5)/COUNT(A$12:A$970) -> 0.075 | C13: =-LN(-LN(B13)) -> -0.95176102 | D13: ='Valeurs Maximales Annuelles'!F8 -> 32.869201 | E13: =D$5+C13*D$4 -> 30.107012 | F13: =1/(1-G13) -> 1.0526316 | G13: 0.05 | H13: =D$5-D$4*LN(-LN(G13)) -> 26.558069 | I13: =-LN(-LN(G13)) -> -1.0971887 | J13: =H13-L13*1.96 -> 9.9830046 | K13: =H13+L13*1.96 -> 43.133134 | L13: =(STDEV(D$12:D$1000)/SQRT(D$8-1))*SQRT(0.7099+0.1165*I13+0.6687*I13*I13) -> 8.4566657 | N13: =RANK(Q13,Q$12:Q$970,1) -> 2 | O13: =(N13-0.5)/COUNT(N$12:N$970) -> 0.075 | P13: =-LN(-LN(O13)) -> -0.95176102 | Q13: ='Valeurs Maximales Annuelles'!H8 -> 42.476169 | R13: =Q$5+P13*Q$4 -> 24.383964 | S13: =1/(1-T13) -> 1.0526316 | T13: 0.05 | U13: =Q$5-Q$4*LN(-LN(T13)) -> 19.638405 | V13: =-LN(-LN(T13)) -> -1.0971887 | W13: =U13-Y13*1.96 -> -2.5253672 | X13: =U13+Y13*1.96 -> 41.802177 | Y13: =(STDEV(Q$12:Q$1000)/SQRT(Q$8-1))*SQRT(0.7099+0.1165*V13+0.6687*V13*V13) -> 11.308047 | AA13: =RANK(AD13,AD$12:AD$970,1) -> 2 | AB13: =(AA13-0.5)/COUNT(AA$12:AA$970) -> 0.075 | AC13: =-LN(-LN(AB13)) -> -0.95176102 | AD13: ='Valeurs Maximales Annuelles'!J8 -> 42.571262 | AE13: =AD$5+AC13*AD$4 -> 30.460427 | AF13: =1/(1-AG13) -> 1.0526316 | AG13: 0.05 | AH13: =AD$5-AD$4*LN(-LN(AG13)) -> 26.691407 | AI13: =-LN(-LN(AG13)) -> -1.0971887 | AJ13: =AH13-AL13*1.96 -> 9.0884893 | AK13: =AH13+AL13*1.96 -> 44.294325 | AL13: =(STDEV(AD$12:AD$1000)/SQRT(AD$8-1))*SQRT(0.7099+0.1165*AI13+0.6687*AI13*AI13) -> 8.9810806 | AN13: =RANK(AQ13,AQ$12:AQ$970,1) -> 2 | AO13: =(AN13-0.5)/COUNT(AN$12:AN$970) -> 0.075 | AP13: =-LN(-LN(AO13)) -> -0.95176102 | AQ13: ='Valeurs Maximales Annuelles'!L8 -> 35.342662 | AR13: =AQ$5+AP13*AQ$4 -> 24.346887 | AS13: =1/(1-AT13) -> 1.0526316 | AT13: 0.05 | AU13: =AQ$5-AQ$4*LN(-LN(AT13)) -> 19.411308 | AV13: =-LN(-LN(AT13)) -> -1.0971887 | AW13: =AU13-AY13*1.96 -> -3.6399355 | AX13: =AU13+AY13*1.96 -> 42.462552 | AY13: =(STDEV(AQ$12:AQ$1000)/SQRT(AQ$8-1))*SQRT(0.7099+0.1165*AV13+0.6687*AV13*AV13) -> 11.760839 | BA13: =RANK(BD13,BD$12:BD$970,1) -> 2 | BB13: =(BA13-0.5)/COUNT(BA$12:BA$970) -> 0.075 | BC13: =-LN(-LN(BB13)) -> -0.95176102 | BD13: ='Valeurs Maximales Annuelles'!N8 -> 37.6056 | BE13: =BD$5+BC13*BD$4 -> 28.342438 | BF13: =1/(1-BG13) -> 1.0526316 | BG13: 0.05 | BH13: =BD$5-BD$4*LN(-LN(BG13)) -> 23.685047 | BI13: =-LN(-LN(BG13)) -> -1.0971887 | BJ13: =BH13-BL13*1.96 -> 1.9330593 | BK13: =BH13+BL13*1.96 -> 45.437036 | BL13: =(STDEV(BD$12:BD$1000)/SQRT(BD$8-1))*SQRT(0.7099+0.1165*BI13+0.6687*BI13*BI13) -> 11.097953 | BN13: =RANK(BQ13,BQ$12:BQ$970,1) -> 2 | BO13: =(BN13-0.5)/COUNT(BN$12:BN$970) -> 0.075 | BP13: =-LN(-LN(BO13)) -> -0.95176102 | BQ13: ='Valeurs Maximales Annuelles'!P8 -> 31.834221 | BR13: =BQ$5+BP13*BQ$4 -> 24.804195 | BS13: =1/(1-BT13) -> 1.0526316 | BT13: 0.05 | BU13: =BQ$5-BQ$4*LN(-LN(BT13)) -> 19.915808 | BV13: =-LN(-LN(BT13)) -> -1.0971887 | BW13: =BU13-BY13*1.96 -> -2.9150319 | BX13: =BU13+BY13*1.96 -> 42.746647 | BY13: =(STDEV(BQ$12:BQ$1000)/SQRT(BQ$8-1))*SQRT(0.7099+0.1165*BV13+0.6687*BV13*BV13) -> 11.648387
A14: =RANK(D14,D$12:D$970,1) -> 3 | B14: =(A14-0.5)/COUNT(A$12:A$970) -> 0.125 | C14: =-LN(-LN(B14)) -> -0.73209937 | D14: ='Valeurs Maximales Annuelles'!F9 -> 42.9274 | E14: =D$5+C14*D$4 -> 35.467522 | F14: =1/(1-G14) -> 1.0999999 | G14: 0.090909 | H14: =D$5-D$4*LN(-LN(G14)) -> 31.99021 | I14: =-LN(-LN(G14)) -> -0.8745918 | J14: =H14-L14*1.96 -> 17.09939 | K14: =H14+L14*1.96 -> 46.88103 | L14: =(STDEV(D$12:D$1000)/SQRT(D$8-1))*SQRT(0.7099+0.1165*I14+0.6687*I14*I14) -> 7.5973572 | N14: =RANK(Q14,Q$12:Q$970,1) -> 3 | O14: =(N14-0.5)/COUNT(N$12:N$970) -> 0.125 | P14: =-LN(-LN(O14)) -> -0.73209937 | Q14: ='Valeurs Maximales Annuelles'!H9 -> 44.542183 | R14: =Q$5+P14*Q$4 -> 31.551908 | S14: =1/(1-T14) -> 1.0999999 | T14: 0.090909 | U14: =Q$5-Q$4*LN(-LN(T14)) -> 26.902131 | V14: =-LN(-LN(T14)) -> -0.8745918 | W14: =U14-Y14*1.96 -> 6.9904897 | X14: =U14+Y14*1.96 -> 46.813772 | Y14: =(STDEV(Q$12:Q$1000)/SQRT(Q$8-1))*SQRT(0.7099+0.1165*V14+0.6687*V14*V14) -> 10.159001 | AA14: =RANK(AD14,AD$12:AD$970,1) -> 3 | AB14: =(AA14-0.5)/COUNT(AA$12:AA$970) -> 0.125 | AC14: =-LN(-LN(AB14)) -> -0.73209937 | AD14: ='Valeurs Maximales Annuelles'!J9 -> 42.932035 | AE14: =AD$5+AC14*AD$4 -> 36.153353 | AF14: =1/(1-AG14) -> 1.0999999 | AG14: 0.090909 | AH14: =AD$5-AD$4*LN(-LN(AG14)) -> 32.460406 | AI14: =-LN(-LN(AG14)) -> -0.8745918 | AJ14: =AH14-AL14*1.96 -> 16.646176 | AK14: =AH14+AL14*1.96 -> 48.274636 | AL14: =(STDEV(AD$12:AD$1000)/SQRT(AD$8-1))*SQRT(0.7099+0.1165*AI14+0.6687*AI14*AI14) -> 8.0684846 | AN14: =RANK(AQ14,AQ$12:AQ$970,1) -> 3 | AO14: =(AN14-0.5)/COUNT(AN$12:AN$970) -> 0.125 | AP14: =-LN(-LN(AO14)) -> -0.73209937 | AQ14: ='Valeurs Maximales Annuelles'!L9 -> 39.48864 | AR14: =AQ$5+AP14*AQ$4 -> 31.801847 | AS14: =1/(1-AT14) -> 1.0999999 | AT14: 0.090909 | AU14: =AQ$5-AQ$4*LN(-LN(AT14)) -> 26.965885 | AV14: =-LN(-LN(AT14)) -> -0.8745918 | AW14: =AU14-AY14*1.96 -> 6.256951 | AX14: =AU14+AY14*1.96 -> 47.674819 | AY14: =(STDEV(AQ$12:AQ$1000)/SQRT(AQ$8-1))*SQRT(0.7099+0.1165*AV14+0.6687*AV14*AV14) -> 10.565783 | BA14: =RANK(BD14,BD$12:BD$970,1) -> 3 | BB14: =(BA14-0.5)/COUNT(BA$12:BA$970) -> 0.125 | BC14: =-LN(-LN(BB14)) -> -0.73209937 | BD14: ='Valeurs Maximales Annuelles'!N9 -> 42.456314 | BE14: =BD$5+BC14*BD$4 -> 35.377208 | BF14: =1/(1-BG14) -> 1.0999999 | BG14: 0.090909 | BH14: =BD$5-BD$4*LN(-LN(BG14)) -> 30.81382 | BI14: =-LN(-LN(BG14)) -> -0.8745918 | BJ14: =BH14-BL14*1.96 -> 11.27212 | BK14: =BH14+BL14*1.96 -> 50.35552 | BL14: =(STDEV(BD$12:BD$1000)/SQRT(BD$8-1))*SQRT(0.7099+0.1165*BI14+0.6687*BI14*BI14) -> 9.9702551 | BN14: =RANK(BQ14,BQ$12:BQ$970,1) -> 3 | BO14: =(BN14-0.5)/COUNT(BN$12:BN$970) -> 0.125 | BP14: =-LN(-LN(BO14)) -> -0.73209937 | BQ14: ='Valeurs Maximales Annuelles'!P9 -> 42.103696 | BR14: =BQ$5+BP14*BQ$4 -> 32.187874 | BS14: =1/(1-BT14) -> 1.0999999 | BT14: 0.090909 | BU14: =BQ$5-BQ$4*LN(-LN(BT14)) -> 27.398151 | BV14: =-LN(-LN(BT14)) -> -0.8745918 | BW14: =BU14-BY14*1.96 -> 6.8872256 | BX14: =BU14+BY14*1.96 -> 47.909077 | BY14: =(STDEV(BQ$12:BQ$1000)/SQRT(BQ$8-1))*SQRT(0.7099+0.1165*BV14+0.6687*BV14*BV14) -> 10.464758
A15: =RANK(D15,D$12:D$970,1) -> 4 | B15: =(A15-0.5)/COUNT(A$12:A$970) -> 0.175 | C15: =-LN(-LN(B15)) -> -0.55559016 | D15: ='Valeurs Maximales Annuelles'!F10 -> 47.048988 | E15: =D$5+C15*D$4 -> 39.774963 | F15: =1/(1-G15) -> 1.1764706 | G15: 0.15 | H15: =D$5-D$4*LN(-LN(G15)) -> 37.706846 | I15: =-LN(-LN(G15)) -> -0.64033694 | J15: =H15-L15*1.96 -> 24.285252 | K15: =H15+L15*1.96 -> 51.128439 | L15: =(STDEV(D$12:D$1000)/SQRT(D$8-1))*SQRT(0.7099+0.1165*I15+0.6687*I15*I15) -> 6.8477518 | N15: =RANK(Q15,Q$12:Q$970,1) -> 4 | O15: =(N15-0.5)/COUNT(N$12:N$970) -> 0.175 | P15: =-LN(-LN(O15)) -> -0.55559016 | Q15: ='Valeurs Maximales Annuelles'!H10 -> 45.203563 | R15: =Q$5+P15*Q$4 -> 37.311713 | S15: =1/(1-T15) -> 1.1764706 | T15: 0.15 | U15: =Q$5-Q$4*LN(-LN(T15)) -> 34.546277 | V15: =-LN(-LN(T15)) -> -0.64033694 | W15: =U15-Y15*1.96 -> 16.599249 | X15: =U15+Y15*1.96 -> 52.493304 | Y15: =(STDEV(Q$12:Q$1000)/SQRT(Q$8-1))*SQRT(0.7099+0.1165*V15+0.6687*V15*V15) -> 9.1566467 | AA15: =RANK(AD15,AD$12:AD$970,1) -> 4 | AB15: =(AA15-0.5)/COUNT(AA$12:AA$970) -> 0.175 | AC15: =-LN(-LN(AB15)) -> -0.55559016 | AD15: ='Valeurs Maximales Annuelles'!J10 -> 46.322729 | AE15: =AD$5+AC15*AD$4 -> 40.727907 | AF15: =1/(1-AG15) -> 1.1764706 | AG15: 0.15 | AH15: =AD$5-AD$4*LN(-LN(AG15)) -> 38.531542 | AI15: =-LN(-LN(AG15)) -> -0.64033694 | AJ15: =AH15-AL15*1.96 -> 24.277648 | AK15: =AH15+AL15*1.96 -> 52.785435 | AL15: =(STDEV(AD$12:AD$1000)/SQRT(AD$8-1))*SQRT(0.7099+0.1165*AI15+0.6687*AI15*AI15) -> 7.2723947 | AN15: =RANK(AQ15,AQ$12:AQ$970,1) -> 4 | AO15: =(AN15-0.5)/COUNT(AN$12:AN$970) -> 0.175 | AP15: =-LN(-LN(AO15)) -> -0.55559016 | AQ15: ='Valeurs Maximales Annuelles'!L10 -> 46.103955 | AR15: =AQ$5+AP15*AQ$4 -> 37.792282 | AS15: =1/(1-AT15) -> 1.1764706 | AT15: 0.15 | AU15: =AQ$5-AQ$4*LN(-LN(AT15)) -> 34.916114 | AV15: =-LN(-LN(AT15)) -> -0.64033694 | AW15: =AU15-AY15*1.96 -> 16.25046 | AX15: =AU15+AY15*1.96 -> 53.581768 | AY15: =(STDEV(AQ$12:AQ$1000)/SQRT(AQ$8-1))*SQRT(0.7099+0.1165*AV15+0.6687*AV15*AV15) -> 9.5232929 | BA15: =RANK(BD15,BD$12:BD$970,1) -> 4 | BB15: =(BA15-0.5)/COUNT(BA$12:BA$970) -> 0.175 | BC15: =-LN(-LN(BB15)) -> -0.55559016 | BD15: ='Valeurs Maximales Annuelles'!N10 -> 44.353999 | BE15: =BD$5+BC15*BD$4 -> 41.03 | BF15: =1/(1-BG15) -> 1.1764706 | BG15: 0.15 | BH15: =BD$5-BD$4*LN(-LN(BG15)) -> 38.315944 | BI15: =-LN(-LN(BG15)) -> -0.64033694 | BJ15: =BH15-BL15*1.96 -> 20.702357 | BK15: =BH15+BL15*1.96 -> 55.929531 | BL15: =(STDEV(BD$12:BD$1000)/SQRT(BD$8-1))*SQRT(0.7099+0.1165*BI15+0.6687*BI15*BI15) -> 8.986524 | BN15: =RANK(BQ15,BQ$12:BQ$970,1) -> 4 | BO15: =(BN15-0.5)/COUNT(BN$12:BN$970) -> 0.175 | BP15: =-LN(-LN(BO15)) -> -0.55559016 | BQ15: ='Valeurs Maximales Annuelles'!P10 -> 46.8602 | BR15: =BQ$5+BP15*BQ$4 -> 38.121032 | BS15: =1/(1-BT15) -> 1.1764706 | BT15: 0.15 | BU15: =BQ$5-BQ$4*LN(-LN(BT15)) -> 35.272365 | BV15: =-LN(-LN(BT15)) -> -0.64033694 | BW15: =BU15-BY15*1.96 -> 16.785182 | BX15: =BU15+BY15*1.96 -> 53.759547 | BY15: =(STDEV(BQ$12:BQ$1000)/SQRT(BQ$8-1))*SQRT(0.7099+0.1165*BV15+0.6687*BV15*BV15) -> 9.432236
A16: =RANK(D16,D$12:D$970,1) -> 5 | B16: =(A16-0.5)/COUNT(A$12:A$970) -> 0.225 | C16: =-LN(-LN(B16)) -> -0.39988616 | D16: ='Valeurs Maximales Annuelles'!F11 -> 48.113587 | E16: =D$5+C16*D$4 -> 43.574683 | F16: =1/(1-G16) -> 1.25 | G16: 0.2 | H16: =D$5-D$4*LN(-LN(G16)) -> 41.720047 | I16: =-LN(-LN(G16)) -> -0.475885 | J16: =H16-L16*1.96 -> 29.085917 | K16: =H16+L16*1.96 -> 54.354177 | L16: =(STDEV(D$12:D$1000)/SQRT(D$8-1))*SQRT(0.7099+0.1165*I16+0.6687*I16*I16) -> 6.4459847 | N16: =RANK(Q16,Q$12:Q$970,1) -> 5 | O16: =(N16-0.5)/COUNT(N$12:N$970) -> 0.225 | P16: =-LN(-LN(O16)) -> -0.39988616 | Q16: ='Valeurs Maximales Annuelles'!H11 -> 45.677841 | R16: =Q$5+P16*Q$4 -> 42.392606 | S16: =1/(1-T16) -> 1.25 | T16: 0.2 | U16: =Q$5-Q$4*LN(-LN(T16)) -> 39.912631 | V16: =-LN(-LN(T16)) -> -0.475885 | W16: =U16-Y16*1.96 -> 23.018581 | X16: =U16+Y16*1.96 -> 56.806682 | Y16: =(STDEV(Q$12:Q$1000)/SQRT(Q$8-1))*SQRT(0.7099+0.1165*V16+0.6687*V16*V16) -> 8.6194135 | AA16: =RANK(AD16,AD$12:AD$970,1) -> 5 | AB16: =(AA16-0.5)/COUNT(AA$12:AA$970) -> 0.225 | AC16: =-LN(-LN(AB16)) -> -0.39988616 | AD16: ='Valeurs Maximales Annuelles'!J11 -> 46.428178 | AE16: =AD$5+AC16*AD$4 -> 44.763256 | AF16: =1/(1-AG16) -> 1.25 | AG16: 0.2 | AH16: =AD$5-AD$4*LN(-LN(AG16)) -> 42.793609 | AI16: =-LN(-LN(AG16)) -> -0.475885 | AJ16: =AH16-AL16*1.96 -> 29.376011 | AK16: =AH16+AL16*1.96 -> 56.211207 | AL16: =(STDEV(AD$12:AD$1000)/SQRT(AD$8-1))*SQRT(0.7099+0.1165*AI16+0.6687*AI16*AI16) -> 6.8457132 | AN16: =RANK(AQ16,AQ$12:AQ$970,1) -> 5 | AO16: =(AN16-0.5)/COUNT(AN$12:AN$970) -> 0.225 | AP16: =-LN(-LN(AO16)) -> -0.39988616 | AQ16: ='Valeurs Maximales Annuelles'!L11 -> 47.186495 | AR16: =AQ$5+AP16*AQ$4 -> 43.076623 | AS16: =1/(1-AT16) -> 1.25 | AT16: 0.2 | AU16: =AQ$5-AQ$4*LN(-LN(AT16)) -> 40.497346 | AV16: =-LN(-LN(AT16)) -> -0.475885 | AW16: =AU16-AY16*1.96 -> 22.926832 | AX16: =AU16+AY16*1.96 -> 58.06786 | AY16: =(STDEV(AQ$12:AQ$1000)/SQRT(AQ$8-1))*SQRT(0.7099+0.1165*AV16+0.6687*AV16*AV16) -> 8.9645481 | BA16: =RANK(BD16,BD$12:BD$970,1) -> 5 | BB16: =(BA16-0.5)/COUNT(BA$12:BA$970) -> 0.225 | BC16: =-LN(-LN(BB16)) -> -0.39988616 | BD16: ='Valeurs Maximales Annuelles'!N11 -> 46.757559 | BE16: =BD$5+BC16*BD$4 -> 46.016495 | BF16: =1/(1-BG16) -> 1.25 | BG16: 0.2 | BH16: =BD$5-BD$4*LN(-LN(BG16)) -> 43.582596 | BI16: =-LN(-LN(BG16)) -> -0.475885 | BJ16: =BH16-BL16*1.96 -> 27.002423 | BK16: =BH16+BL16*1.96 -> 60.162769 | BL16: =(STDEV(BD$12:BD$1000)/SQRT(BD$8-1))*SQRT(0.7099+0.1165*BI16+0.6687*BI16*BI16) -> 8.4592721 | BN16: =RANK(BQ16,BQ$12:BQ$970,1) -> 5 | BO16: =(BN16-0.5)/COUNT(BN$12:BN$970) -> 0.225 | BP16: =-LN(-LN(BO16)) -> -0.39988616 | BQ16: ='Valeurs Maximales Annuelles'!P11 -> 47.69377 | BR16: =BQ$5+BP16*BQ$4 -> 43.354846 | BS16: =1/(1-BT16) -> 1.25 | BT16: 0.2 | BU16: =BQ$5-BQ$4*LN(-LN(BT16)) -> 40.800231 | BV16: =-LN(-LN(BT16)) -> -0.475885 | BW16: =BU16-BY16*1.96 -> 23.397717 | BX16: =BU16+BY16*1.96 -> 58.202745 | BY16: =(STDEV(BQ$12:BQ$1000)/SQRT(BQ$8-1))*SQRT(0.7099+0.1165*BV16+0.6687*BV16*BV16) -> 8.8788336
A17: =RANK(D17,D$12:D$970,1) -> 6 | B17: =(A17-0.5)/COUNT(A$12:A$970) -> 0.275 | C17: =-LN(-LN(B17)) -> -0.25540486 | D17: ='Valeurs Maximales Annuelles'!F12 -> 48.386913 | E17: =D$5+C17*D$4 -> 47.100531 | F17: =1/(1-G17) -> 1.3333333 | G17: 0.25 | H17: =D$5-D$4*LN(-LN(G17)) -> 45.362285 | I17: =-LN(-LN(G17)) -> -0.32663426 | J17: =H17-L17*1.96 -> 33.229639 | K17: =H17+L17*1.96 -> 57.494932 | L17: =(STDEV(D$12:D$1000)/SQRT(D$8-1))*SQRT(0.7099+0.1165*I17+0.6687*I17*I17) -> 6.1901258 | N17: =RANK(Q17,Q$12:Q$970,1) -> 6 | O17: =(N17-0.5)/COUNT(N$12:N$970) -> 0.275 | P17: =-LN(-LN(O17)) -> -0.25540486 | Q17: ='Valeurs Maximales Annuelles'!H12 -> 47.69377 | R17: =Q$5+P17*Q$4 -> 47.107284 | S17: =1/(1-T17) -> 1.3333333 | T17: 0.25 | U17: =Q$5-Q$4*LN(-LN(T17)) -> 44.782944 | V17: =-LN(-LN(T17)) -> -0.32663426 | W17: =U17-Y17*1.96 -> 28.559465 | X17: =U17+Y17*1.96 -> 61.006423 | Y17: =(STDEV(Q$12:Q$1000)/SQRT(Q$8-1))*SQRT(0.7099+0.1165*V17+0.6687*V17*V17) -> 8.2772852 | AA17: =RANK(AD17,AD$12:AD$970,1) -> 6 | AB17: =(AA17-0.5)/COUNT(AA$12:AA$970) -> 0.275 | AC17: =-LN(-LN(AB17)) -> -0.25540486 | AD17: ='Valeurs Maximales Annuelles'!J12 -> 46.90432 | AE17: =AD$5+AC17*AD$4 -> 48.507748 | AF17: =1/(1-AG17) -> 1.3333333 | AG17: 0.25 | AH17: =AD$5-AD$4*LN(-LN(AG17)) -> 46.66171 | AI17: =-LN(-LN(AG17)) -> -0.32663426 | AJ17: =AH17-AL17*1.96 -> 33.776694 | AK17: =AH17+AL17*1.96 -> 59.546727 | AL17: =(STDEV(AD$12:AD$1000)/SQRT(AD$8-1))*SQRT(0.7099+0.1165*AI17+0.6687*AI17*AI17) -> 6.5739879 | AN17: =RANK(AQ17,AQ$12:AQ$970,1) -> 6 | AO17: =(AN17-0.5)/COUNT(AN$12:AN$970) -> 0.275 | AP17: =-LN(-LN(AO17)) -> -0.25540486 | AQ17: ='Valeurs Maximales Annuelles'!L12 -> 48.560495 | AR17: =AQ$5+AP17*AQ$4 -> 47.980083 | AS17: =1/(1-AT17) -> 1.3333333 | AT17: 0.25 | AU17: =AQ$5-AQ$4*LN(-LN(AT17)) -> 45.562673 | AV17: =-LN(-LN(AT17)) -> -0.32663426 | AW17: =AU17-AY17*1.96 -> 28.689581 | AX17: =AU17+AY17*1.96 -> 62.435765 | AY17: =(STDEV(AQ$12:AQ$1000)/SQRT(AQ$8-1))*SQRT(0.7099+0.1165*AV17+0.6687*AV17*AV17) -> 8.6087204 | BA17: =RANK(BD17,BD$12:BD$970,1) -> 6 | BB17: =(BA17-0.5)/COUNT(BA$12:BA$970) -> 0.275 | BC17: =-LN(-LN(BB17)) -> -0.25540486 | BD17: ='Valeurs Maximales Annuelles'!N12 -> 49.904619 | BE17: =BD$5+BC17*BD$4 -> 50.643578 | BF17: =1/(1-BG17) -> 1.3333333 | BG17: 0.25 | BH17: =BD$5-BD$4*LN(-LN(BG17)) -> 48.362422 | BI17: =-LN(-LN(BG17)) -> -0.32663426 | BJ17: =BH17-BL17*1.96 -> 32.440362 | BK17: =BH17+BL17*1.96 -> 64.284483 | BL17: =(STDEV(BD$12:BD$1000)/SQRT(BD$8-1))*SQRT(0.7099+0.1165*BI17+0.6687*BI17*BI17) -> 8.1235003 | BN17: =RANK(BQ17,BQ$12:BQ$970,1) -> 6 | BO17: =(BN17-0.5)/COUNT(BN$12:BN$970) -> 0.275 | BP17: =-LN(-LN(BO17)) -> -0.25540486 | BQ17: ='Valeurs Maximales Annuelles'!P12 -> 48.779421 | BR17: =BQ$5+BP17*BQ$4 -> 48.211422 | BS17: =1/(1-BT17) -> 1.3333333 | BT17: 0.25 | BU17: =BQ$5-BQ$4*LN(-LN(BT17)) -> 45.817126 | BV17: =-LN(-LN(BT17)) -> -0.32663426 | BW17: =BU17-BY17*1.96 -> 29.105366 | BX17: =BU17+BY17*1.96 -> 62.528886 | BY17: =(STDEV(BQ$12:BQ$1000)/SQRT(BQ$8-1))*SQRT(0.7099+0.1165*BV17+0.6687*BV17*BV17) -> 8.5264082
A18: =RANK(D18,D$12:D$970,1) -> 7 | B18: =(A18-0.5)/COUNT(A$12:A$970) -> 0.325 | C18: =-LN(-LN(B18)) -> -0.11683156 | D18: ='Valeurs Maximales Annuelles'!F13 -> 50.666395 | E18: =D$5+C18*D$4 -> 50.482203 | F18: =1/(1-G18) -> 1.4285714 | G18: 0.3 | H18: =D$5-D$4*LN(-LN(G18)) -> 48.80336 | I18: =-LN(-LN(G18)) -> -0.18562676 | J18: =H18-L18*1.96 -> 36.933742 | K18: =H18+L18*1.96 -> 60.672978 | L18: =(STDEV(D$12:D$1000)/SQRT(D$8-1))*SQRT(0.7099+0.1165*I18+0.6687*I18*I18) -> 6.0559274 | N18: =RANK(Q18,Q$12:Q$970,1) -> 7 | O18: =(N18-0.5)/COUNT(N$12:N$970) -> 0.325 | P18: =-LN(-LN(O18)) -> -0.11683156 | Q18: ='Valeurs Maximales Annuelles'!H13 -> 50.334666 | R18: =Q$5+P18*Q$4 -> 51.629173 | S18: =1/(1-T18) -> 1.4285714 | T18: 0.3 | U18: =Q$5-Q$4*LN(-LN(T18)) -> 49.384265 | V18: =-LN(-LN(T18)) -> -0.18562676 | W18: =U18-Y18*1.96 -> 33.512502 | X18: =U18+Y18*1.96 -> 65.256028 | Y18: =(STDEV(Q$12:Q$1000)/SQRT(Q$8-1))*SQRT(0.7099+0.1165*V18+0.6687*V18*V18) -> 8.0978384 | AA18: =RANK(AD18,AD$12:AD$970,1) -> 7 | AB18: =(AA18-0.5)/COUNT(AA$12:AA$970) -> 0.325 | AC18: =-LN(-LN(AB18)) -> -0.11683156 | AD18: ='Valeurs Maximales Annuelles'!J13 -> 48.409488 | AE18: =AD$5+AC18*AD$4 -> 52.099124 | AF18: =1/(1-AG18) -> 1.4285714 | AG18: 0.3 | AH18: =AD$5-AD$4*LN(-LN(AG18)) -> 50.316173 | AI18: =-LN(-LN(AG18)) -> -0.18562676 | AJ18: =AH18-AL18*1.96 -> 37.710497 | AK18: =AH18+AL18*1.96 -> 62.92185 | AL18: =(STDEV(AD$12:AD$1000)/SQRT(AD$8-1))*SQRT(0.7099+0.1165*AI18+0.6687*AI18*AI18) -> 6.4314677 | AN18: =RANK(AQ18,AQ$12:AQ$970,1) -> 7 | AO18: =(AN18-0.5)/COUNT(AN$12:AN$970) -> 0.325 | AP18: =-LN(-LN(AO18)) -> -0.11683156 | AQ18: ='Valeurs Maximales Annuelles'!L13 -> 49.235622 | AR18: =AQ$5+AP18*AQ$4 -> 52.683036 | AS18: =1/(1-AT18) -> 1.4285714 | AT18: 0.3 | AU18: =AQ$5-AQ$4*LN(-LN(AT18)) -> 50.348239 | AV18: =-LN(-LN(AT18)) -> -0.18562676 | AW18: =AU18-AY18*1.96 -> 33.840945 | AX18: =AU18+AY18*1.96 -> 66.855532 | AY18: =(STDEV(AQ$12:AQ$1000)/SQRT(AQ$8-1))*SQRT(0.7099+0.1165*AV18+0.6687*AV18*AV18) -> 8.4220883 | BA18: =RANK(BD18,BD$12:BD$970,1) -> 7 | BB18: =(BA18-0.5)/COUNT(BA$12:BA$970) -> 0.325 | BC18: =-LN(-LN(BB18)) -> -0.11683156 | BD18: ='Valeurs Maximales Annuelles'!N13 -> 50.365691 | BE18: =BD$5+BC18*BD$4 -> 55.081454 | BF18: =1/(1-BG18) -> 1.4285714 | BG18: 0.3 | BH18: =BD$5-BD$4*LN(-LN(BG18)) -> 52.878255 | BI18: =-LN(-LN(BG18)) -> -0.18562676 | BJ18: =BH18-BL18*1.96 -> 37.301375 | BK18: =BH18+BL18*1.96 -> 68.455134 | BL18: =(STDEV(BD$12:BD$1000)/SQRT(BD$8-1))*SQRT(0.7099+0.1165*BI18+0.6687*BI18*BI18) -> 7.9473874 | BN18: =RANK(BQ18,BQ$12:BQ$970,1) -> 7 | BO18: =(BN18-0.5)/COUNT(BN$12:BN$970) -> 0.325 | BP18: =-LN(-LN(BO18)) -> -0.11683156 | BQ18: ='Valeurs Maximales Annuelles'!P13 -> 52.934498 | BR18: =BQ$5+BP18*BQ$4 -> 52.869408 | BS18: =1/(1-BT18) -> 1.4285714 | BT18: 0.3 | BU18: =BQ$5-BQ$4*LN(-LN(BT18)) -> 50.556935 | BV18: =-LN(-LN(BT18)) -> -0.18562676 | BW18: =BU18-BY18*1.96 -> 34.207476 | BX18: =BU18+BY18*1.96 -> 66.906393 | BY18: =(STDEV(BQ$12:BQ$1000)/SQRT(BQ$8-1))*SQRT(0.7099+0.1165*BV18+0.6687*BV18*BV18) -> 8.3415606
A19: =RANK(D19,D$12:D$970,1) -> 8 | B19: =(A19-0.5)/COUNT(A$12:A$970) -> 0.375 | C19: =-LN(-LN(B19)) -> 0.019356889 | D19: ='Valeurs Maximales Annuelles'!F14 -> 50.704898 | E19: =D$5+C19*D$4 -> 53.805676 | F19: =1/(1-G19) -> 1.5384615 | G19: 0.35 | H19: =D$5-D$4*LN(-LN(G19)) -> 52.146785 | I19: =-LN(-LN(G19)) -> -0.048620745 | J19: =H19-L19*1.96 -> 40.323141 | K19: =H19+L19*1.96 -> 63.970428 | L19: =(STDEV(D$12:D$1000)/SQRT(D$8-1))*SQRT(0.7099+0.1165*I19+0.6687*I19*I19) -> 6.032471 | N19: =RANK(Q19,Q$12:Q$970,1) -> 8 | O19: =(N19-0.5)/COUNT(N$12:N$970) -> 0.375 | P19: =-LN(-LN(O19)) -> 0.019356889 | Q19: ='Valeurs Maximales Annuelles'!H14 -> 53.529602 | R19: =Q$5+P19*Q$4 -> 56.07324 | S19: =1/(1-T19) -> 1.5384615 | T19: 0.35 | U19: =Q$5-Q$4*LN(-LN(T19)) -> 53.855011 | V19: =-LN(-LN(T19)) -> -0.048620745 | W19: =U19-Y19*1.96 -> 38.044724 | X19: =U19+Y19*1.96 -> 69.665298 | Y19: =(STDEV(Q$12:Q$1000)/SQRT(Q$8-1))*SQRT(0.7099+0.1165*V19+0.6687*V19*V19) -> 8.0664731 | AA19: =RANK(AD19,AD$12:AD$970,1) -> 8 | AB19: =(AA19-0.5)/COUNT(AA$12:AA$970) -> 0.375 | AC19: =-LN(-LN(AB19)) -> 0.019356889 | AD19: ='Valeurs Maximales Annuelles'!J14 -> 48.725679 | AE19: =AD$5+AC19*AD$4 -> 55.628693 | AF19: =1/(1-AG19) -> 1.5384615 | AG19: 0.35 | AH19: =AD$5-AD$4*LN(-LN(AG19)) -> 53.86693 | AI19: =-LN(-LN(AG19)) -> -0.048620745 | AJ19: =AH19-AL19*1.96 -> 41.310079 | AK19: =AH19+AL19*1.96 -> 66.423781 | AL19: =(STDEV(AD$12:AD$1000)/SQRT(AD$8-1))*SQRT(0.7099+0.1165*AI19+0.6687*AI19*AI19) -> 6.4065567 | AN19: =RANK(AQ19,AQ$12:AQ$970,1) -> 8 | AO19: =(AN19-0.5)/COUNT(AN$12:AN$970) -> 0.375 | AP19: =-LN(-LN(AO19)) -> 0.019356889 | AQ19: ='Valeurs Maximales Annuelles'!L14 -> 53.175628 | AR19: =AQ$5+AP19*AQ$4 -> 57.30505 | AS19: =1/(1-AT19) -> 1.5384615 | AT19: 0.35 | AU19: =AQ$5-AQ$4*LN(-LN(AT19)) -> 54.998 | AV19: =-LN(-LN(AT19)) -> -0.048620745 | AW19: =AU19-AY19*1.96 -> 38.554644 | AX19: =AU19+AY19*1.96 -> 71.441355 | AY19: =(STDEV(AQ$12:AQ$1000)/SQRT(AQ$8-1))*SQRT(0.7099+0.1165*AV19+0.6687*AV19*AV19) -> 8.3894671 | BA19: =RANK(BD19,BD$12:BD$970,1) -> 8 | BB19: =(BA19-0.5)/COUNT(BA$12:BA$970) -> 0.375 | BC19: =-LN(-LN(BB19)) -> 0.019356889 | BD19: ='Valeurs Maximales Annuelles'!N14 -> 51.343814 | BE19: =BD$5+BC19*BD$4 -> 59.442954 | BF19: =1/(1-BG19) -> 1.5384615 | BG19: 0.35 | BH19: =BD$5-BD$4*LN(-LN(BG19)) -> 57.265938 | BI19: =-LN(-LN(BG19)) -> -0.048620745 | BJ19: =BH19-BL19*1.96 -> 41.749392 | BK19: =BH19+BL19*1.96 -> 72.782484 | BL19: =(STDEV(BD$12:BD$1000)/SQRT(BD$8-1))*SQRT(0.7099+0.1165*BI19+0.6687*BI19*BI19) -> 7.9166049 | BN19: =RANK(BQ19,BQ$12:BQ$970,1) -> 8 | BO19: =(BN19-0.5)/COUNT(BN$12:BN$970) -> 0.375 | BP19: =-LN(-LN(BO19)) -> 0.019356889 | BQ19: ='Valeurs Maximales Annuelles'!P14 -> 54.546707 | BR19: =BQ$5+BP19*BQ$4 -> 57.447229 | BS19: =1/(1-BT19) -> 1.5384615 | BT19: 0.35 | BU19: =BQ$5-BQ$4*LN(-LN(BT19)) -> 55.162237 | BV19: =-LN(-LN(BT19)) -> -0.048620745 | BW19: =BU19-BY19*1.96 -> 38.876105 | BX19: =BU19+BY19*1.96 -> 71.44837 | BY19: =(STDEV(BQ$12:BQ$1000)/SQRT(BQ$8-1))*SQRT(0.7099+0.1165*BV19+0.6687*BV19*BV19) -> 8.3092513
A20: =RANK(D20,D$12:D$970,1) -> 9 | B20: =(A20-0.5)/COUNT(A$12:A$970) -> 0.425 | C20: =-LN(-LN(B20)) -> 0.15587504 | D20: ='Valeurs Maximales Annuelles'!F15 -> 52.027841 | E20: =D$5+C20*D$4 -> 57.137195 | F20: =1/(1-G20) -> 1.6666667 | G20: 0.4 | H20: =D$5-D$4*LN(-LN(G20)) -> 55.466692 | I20: =-LN(-LN(G20)) -> 0.087421572 | J20: =H20-L20*1.96 -> 43.481834 | K20: =H20+L20*1.96 -> 67.451549 | L20: =(STDEV(D$12:D$1000)/SQRT(D$8-1))*SQRT(0.7099+0.1165*I20+0.6687*I20*I20) -> 6.1147232 | N20: =RANK(Q20,Q$12:Q$970,1) -> 9 | O20: =(N20-0.5)/COUNT(N$12:N$970) -> 0.425 | P20: =-LN(-LN(O20)) -> 0.15587504 | Q20: ='Valeurs Maximales Annuelles'!H15 -> 53.938448 | R20: =Q$5+P20*Q$4 -> 60.528066 | S20: =1/(1-T20) -> 1.6666667 | T20: 0.4 | U20: =Q$5-Q$4*LN(-LN(T20)) -> 58.29431 | V20: =-LN(-LN(T20)) -> 0.087421572 | W20: =U20-Y20*1.96 -> 42.268451 | X20: =U20+Y20*1.96 -> 74.320169 | Y20: =(STDEV(Q$12:Q$1000)/SQRT(Q$8-1))*SQRT(0.7099+0.1165*V20+0.6687*V20*V20) -> 8.1764587 | AA20: =RANK(AD20,AD$12:AD$970,1) -> 9 | AB20: =(AA20-0.5)/COUNT(AA$12:AA$970) -> 0.425 | AC20: =-LN(-LN(AB20)) -> 0.15587504 | AD20: ='Valeurs Maximales Annuelles'!J15 -> 53.177466 | AE20: =AD$5+AC20*AD$4 -> 59.166806 | AF20: =1/(1-AG20) -> 1.6666667 | AG20: 0.4 | AH20: =AD$5-AD$4*LN(-LN(AG20)) -> 57.392711 | AI20: =-LN(-LN(AG20)) -> 0.087421572 | AJ20: =AH20-AL20*1.96 -> 44.664649 | AK20: =AH20+AL20*1.96 -> 70.120774 | AL20: =(STDEV(AD$12:AD$1000)/SQRT(AD$8-1))*SQRT(0.7099+0.1165*AI20+0.6687*AI20*AI20) -> 6.4939095 | AN20: =RANK(AQ20,AQ$12:AQ$970,1) -> 9 | AO20: =(AN20-0.5)/COUNT(AN$12:AN$970) -> 0.425 | AP20: =-LN(-LN(AO20)) -> 0.15587504 | AQ20: ='Valeurs Maximales Annuelles'!L15 -> 57.815447 | AR20: =AQ$5+AP20*AQ$4 -> 61.938254 | AS20: =1/(1-AT20) -> 1.6666667 | AT20: 0.4 | AU20: =AQ$5-AQ$4*LN(-LN(AT20)) -> 59.615055 | AV20: =-LN(-LN(AT20)) -> 0.087421572 | AW20: =AU20-AY20*1.96 -> 42.947496 | AX20: =AU20+AY20*1.96 -> 76.282614 | AY20: =(STDEV(AQ$12:AQ$1000)/SQRT(AQ$8-1))*SQRT(0.7099+0.1165*AV20+0.6687*AV20*AV20) -> 8.5038567 | BA20: =RANK(BD20,BD$12:BD$970,1) -> 9 | BB20: =(BA20-0.5)/COUNT(BA$12:BA$970) -> 0.425 | BC20: =-LN(-LN(BB20)) -> 0.15587504 | BD20: ='Valeurs Maximales Annuelles'!N15 -> 54.546707 | BE20: =BD$5+BC20*BD$4 -> 63.815013 | BF20: =1/(1-BG20) -> 1.6666667 | BG20: 0.4 | BH20: =BD$5-BD$4*LN(-LN(BG20)) -> 61.622758 | BI20: =-LN(-LN(BG20)) -> 0.087421572 | BJ20: =BH20-BL20*1.96 -> 45.894646 | BK20: =BH20+BL20*1.96 -> 77.35087 | BL20: =(STDEV(BD$12:BD$1000)/SQRT(BD$8-1))*SQRT(0.7099+0.1165*BI20+0.6687*BI20*BI20) -> 8.024547 | BN20: =RANK(BQ20,BQ$12:BQ$970,1) -> 9 | BO20: =(BN20-0.5)/COUNT(BN$12:BN$970) -> 0.425 | BP20: =-LN(-LN(BO20)) -> 0.15587504 | BQ20: ='Valeurs Maximales Annuelles'!P15 -> 60.656313 | BR20: =BQ$5+BP20*BQ$4 -> 62.036132 | BS20: =1/(1-BT20) -> 1.6666667 | BT20: 0.4 | BU20: =BQ$5-BQ$4*LN(-LN(BT20)) -> 59.735146 | BV20: =-LN(-LN(BT20)) -> 0.087421572 | BW20: =BU20-BY20*1.96 -> 43.226954 | BX20: =BU20+BY20*1.96 -> 76.243339 | BY20: =(STDEV(BQ$12:BQ$1000)/SQRT(BQ$8-1))*SQRT(0.7099+0.1165*BV20+0.6687*BV20*BV20) -> 8.4225471
A21: =RANK(D21,D$12:D$970,1) -> 10 | B21: =(A21-0.5)/COUNT(A$12:A$970) -> 0.475 | C21: =-LN(-LN(B21)) -> 0.29512238 | D21: ='Valeurs Maximales Annuelles'!F16 -> 53.786801 | E21: =D$5+C21*D$4 -> 60.535316 | F21: =1/(1-G21) -> 1.8181818 | G21: 0.45 | H21: =D$5-D$4*LN(-LN(G21)) -> 58.824346 | I21: =-LN(-LN(G21)) -> 0.22501067 | J21: =H21-L21*1.96 -> 46.475047 | K21: =H21+L21*1.96 -> 71.173644 | L21: =(STDEV(D$12:D$1000)/SQRT(D$8-1))*SQRT(0.7099+0.1165*I21+0.6687*I21*I21) -> 6.3006625 | N21: =RANK(Q21,Q$12:Q$970,1) -> 10 | O21: =(N21-0.5)/COUNT(N$12:N$970) -> 0.475 | P21: =-LN(-LN(O21)) -> 0.29512238 | Q21: ='Valeurs Maximales Annuelles'!H16 -> 55.149309 | R21: =Q$5+P21*Q$4 -> 65.07195 | S21: =1/(1-T21) -> 1.8181818 | T21: 0.45 | U21: =Q$5-Q$4*LN(-LN(T21)) -> 62.784082 | V21: =-LN(-LN(T21)) -> 0.22501067 | W21: =U21-Y21*1.96 -> 46.270902 | X21: =U21+Y21*1.96 -> 79.297263 | Y21: =(STDEV(Q$12:Q$1000)/SQRT(Q$8-1))*SQRT(0.7099+0.1165*V21+0.6687*V21*V21) -> 8.4250922 | AA21: =RANK(AD21,AD$12:AD$970,1) -> 10 | AB21: =(AA21-0.5)/COUNT(AA$12:AA$970) -> 0.475 | AC21: =-LN(-LN(AB21)) -> 0.29512238 | AD21: ='Valeurs Maximales Annuelles'!J16 -> 53.300994 | AE21: =AD$5+AC21*AD$4 -> 62.775651 | AF21: =1/(1-AG21) -> 1.8181818 | AG21: 0.45 | AH21: =AD$5-AD$4*LN(-LN(AG21)) -> 60.95858 | AI21: =-LN(-LN(AG21)) -> 0.22501067 | AJ21: =AH21-AL21*1.96 -> 47.843477 | AK21: =AH21+AL21*1.96 -> 74.073684 | AL21: =(STDEV(AD$12:AD$1000)/SQRT(AD$8-1))*SQRT(0.7099+0.1165*AI21+0.6687*AI21*AI21) -> 6.6913793 | AN21: =RANK(AQ21,AQ$12:AQ$970,1) -> 10 | AO21: =(AN21-0.5)/COUNT(AN$12:AN$970) -> 0.475 | AP21: =-LN(-LN(AO21)) -> 0.29512238 | AQ21: ='Valeurs Maximales Annuelles'!L16 -> 58.036922 | AR21: =AQ$5+AP21*AQ$4 -> 66.664083 | AS21: =1/(1-AT21) -> 1.8181818 | AT21: 0.45 | AU21: =AQ$5-AQ$4*LN(-LN(AT21)) -> 64.284605 | AV21: =-LN(-LN(AT21)) -> 0.22501067 | AW21: =AU21-AY21*1.96 -> 47.110211 | AX21: =AU21+AY21*1.96 -> 81.458999 | AY21: =(STDEV(AQ$12:AQ$1000)/SQRT(AQ$8-1))*SQRT(0.7099+0.1165*AV21+0.6687*AV21*AV21) -> 8.7624459 | BA21: =RANK(BD21,BD$12:BD$970,1) -> 10 | BB21: =(BA21-0.5)/COUNT(BA$12:BA$970) -> 0.475 | BC21: =-LN(-LN(BB21)) -> 0.29512238 | BD21: ='Valeurs Maximales Annuelles'!N16 -> 55.72396 | BE21: =BD$5+BC21*BD$4 -> 68.274476 | BF21: =1/(1-BG21) -> 1.8181818 | BG21: 0.45 | BH21: =BD$5-BD$4*LN(-LN(BG21)) -> 66.029115 | BI21: =-LN(-LN(BG21)) -> 0.22501067 | BJ21: =BH21-BL21*1.96 -> 49.822735 | BK21: =BH21+BL21*1.96 -> 82.235495 | BL21: =(STDEV(BD$12:BD$1000)/SQRT(BD$8-1))*SQRT(0.7099+0.1165*BI21+0.6687*BI21*BI21) -> 8.2685612 | BN21: =RANK(BQ21,BQ$12:BQ$970,1) -> 10 | BO21: =(BN21-0.5)/COUNT(BN$12:BN$970) -> 0.475 | BP21: =-LN(-LN(BO21)) -> 0.29512238 | BQ21: ='Valeurs Maximales Annuelles'!P16 -> 62.855809 | BR21: =BQ$5+BP21*BQ$4 -> 66.716775 | BS21: =1/(1-BT21) -> 1.8181818 | BT21: 0.45 | BU21: =BQ$5-BQ$4*LN(-LN(BT21)) -> 64.360049 | BV21: =-LN(-LN(BT21)) -> 0.22501067 | BW21: =BU21-BY21*1.96 -> 47.349868 | BX21: =BU21+BY21*1.96 -> 81.37023 | BY21: =(STDEV(BQ$12:BQ$1000)/SQRT(BQ$8-1))*SQRT(0.7099+0.1165*BV21+0.6687*BV21*BV21) -> 8.6786639
A22: =RANK(D22,D$12:D$970,1) -> 11 | B22: =(A22-0.5)/COUNT(A$12:A$970) -> 0.525 | C22: =-LN(-LN(B22)) -> 0.43950233 | D22: ='Valeurs Maximales Annuelles'!F17 -> 55.202284 | E22: =D$5+C22*D$4 -> 64.05869 | F22: =1/(1-G22) -> 2 | G22: 0.5 | H22: =D$5-D$4*LN(-LN(G22)) -> 62.277494 | I22: =-LN(-LN(G22)) -> 0.36651292 | J22: =H22-L22*1.96 -> 49.360204 | K22: =H22+L22*1.96 -> 75.194784 | L22: =(STDEV(D$12:D$1000)/SQRT(D$8-1))*SQRT(0.7099+0.1165*I22+0.6687*I22*I22) -> 6.5904539 | N22: =RANK(Q22,Q$12:Q$970,1) -> 11 | O22: =(N22-0.5)/COUNT(N$12:N$970) -> 0.525 | P22: =-LN(-LN(O22)) -> 0.43950233 | Q22: ='Valeurs Maximales Annuelles'!H17 -> 58.186632 | R22: =Q$5+P22*Q$4 -> 69.78332 | S22: =1/(1-T22) -> 2 | T22: 0.5 | U22: =Q$5-Q$4*LN(-LN(T22)) -> 67.401548 | V22: =-LN(-LN(T22)) -> 0.36651292 | W22: =U22-Y22*1.96 -> 50.128864 | X22: =U22+Y22*1.96 -> 84.674233 | Y22: =(STDEV(Q$12:Q$1000)/SQRT(Q$8-1))*SQRT(0.7099+0.1165*V22+0.6687*V22*V22) -> 8.8125942 | AA22: =RANK(AD22,AD$12:AD$970,1) -> 11 | AB22: =(AA22-0.5)/COUNT(AA$12:AA$970) -> 0.525 | AC22: =-LN(-LN(AB22)) -> 0.43950233 | AD22: ='Valeurs Maximales Annuelles'!J17 -> 58.509511 | AE22: =AD$5+AC22*AD$4 -> 66.517517 | AF22: =1/(1-AG22) -> 2 | AG22: 0.5 | AH22: =AD$5-AD$4*LN(-LN(AG22)) -> 64.625865 | AI22: =-LN(-LN(AG22)) -> 0.36651292 | AJ22: =AH22-AL22*1.96 -> 50.907548 | AK22: =AH22+AL22*1.96 -> 78.344182 | AL22: =(STDEV(AD$12:AD$1000)/SQRT(AD$8-1))*SQRT(0.7099+0.1165*AI22+0.6687*AI22*AI22) -> 6.9991412 | AN22: =RANK(AQ22,AQ$12:AQ$970,1) -> 11 | AO22: =(AN22-0.5)/COUNT(AN$12:AN$970) -> 0.525 | AP22: =-LN(-LN(AO22)) -> 0.43950233 | AQ22: ='Valeurs Maximales Annuelles'!L17 -> 63.557696 | AR22: =AQ$5+AP22*AQ$4 -> 71.564104 | AS22: =1/(1-AT22) -> 2 | AT22: 0.5 | AU22: =AQ$5-AQ$4*LN(-LN(AT22)) -> 69.086962 | AV22: =-LN(-LN(AT22)) -> 0.36651292 | AW22: =AU22-AY22*1.96 -> 51.122652 | AX22: =AU22+AY22*1.96 -> 87.051271 | AY22: =(STDEV(AQ$12:AQ$1000)/SQRT(AQ$8-1))*SQRT(0.7099+0.1165*AV22+0.6687*AV22*AV22) -> 9.165464 | BA22: =RANK(BD22,BD$12:BD$970,1) -> 11 | BB22: =(BA22-0.5)/COUNT(BA$12:BA$970) -> 0.525 | BC22: =-LN(-LN(BB22)) -> 0.43950233 | BD22: ='Valeurs Maximales Annuelles'!N17 -> 65.458561 | BE22: =BD$5+BC22*BD$4 -> 72.898313 | BF22: =1/(1-BG22) -> 2 | BG22: 0.5 | BH22: =BD$5-BD$4*LN(-LN(BG22)) -> 70.560792 | BI22: =-LN(-LN(BG22)) -> 0.36651292 | BJ22: =BH22-BL22*1.96 -> 53.609019 | BK22: =BH22+BL22*1.96 -> 87.512565 | BL22: =(STDEV(BD$12:BD$1000)/SQRT(BD$8-1))*SQRT(0.7099+0.1165*BI22+0.6687*BI22*BI22) -> 8.6488637 | BN22: =RANK(BQ22,BQ$12:BQ$970,1) -> 11 | BO22: =(BN22-0.5)/COUNT(BN$12:BN$970) -> 0.525 | BP22: =-LN(-LN(BO22)) -> 0.43950233 | BQ22: ='Valeurs Maximales Annuelles'!P17 -> 64.492448 | BR22: =BQ$5+BP22*BQ$4 -> 71.569944 | BS22: =1/(1-BT22) -> 2 | BT22: 0.5 | BU22: =BQ$5-BQ$4*LN(-LN(BT22)) -> 69.116487 | BV22: =-LN(-LN(BT22)) -> 0.36651292 | BW22: =BU22-BY22*1.96 -> 51.323943 | BX22: =BU22+BY22*1.96 -> 86.909031 | BY22: =(STDEV(BQ$12:BQ$1000)/SQRT(BQ$8-1))*SQRT(0.7099+0.1165*BV22+0.6687*BV22*BV22) -> 9.0778285
A23: =RANK(D23,D$12:D$970,1) -> 12 | B23: =(A23-0.5)/COUNT(A$12:A$970) -> 0.575 | C23: =-LN(-LN(B23)) -> 0.59170089 | D23: ='Valeurs Maximales Annuelles'!F18 -> 68.347725 | E23: =D$5+C23*D$4 -> 67.772866 | F23: =1/(1-G23) -> 2.2222222 | G23: 0.55 | H23: =D$5-D$4*LN(-LN(G23)) -> 65.887361 | I23: =-LN(-LN(G23)) -> 0.51443714 | J23: =H23-L23*1.96 -> 52.193225 | K23: =H23+L23*1.96 -> 79.581497 | L23: =(STDEV(D$12:D$1000)/SQRT(D$8-1))*SQRT(0.7099+0.1165*I23+0.6687*I23*I23) -> 6.9868041 | N23: =RANK(Q23,Q$12:Q$970,1) -> 12 | O23: =(N23-0.5)/COUNT(N$12:N$970) -> 0.575 | P23: =-LN(-LN(O23)) -> 0.59170089 | Q23: ='Valeurs Maximales Annuelles'!H18 -> 58.467666 | R23: =Q$5+P23*Q$4 -> 74.749825 | S23: =1/(1-T23) -> 2.2222222 | T23: 0.55 | U23: =Q$5-Q$4*LN(-LN(T23)) -> 72.228574 | V23: =-LN(-LN(T23)) -> 0.51443714 | W23: =U23-Y23*1.96 -> 53.917109 | X23: =U23+Y23*1.96 -> 90.540039 | Y23: =(STDEV(Q$12:Q$1000)/SQRT(Q$8-1))*SQRT(0.7099+0.1165*V23+0.6687*V23*V23) -> 9.342584 | AA23: =RANK(AD23,AD$12:AD$970,1) -> 12 | AB23: =(AA23-0.5)/COUNT(AA$12:AA$970) -> 0.575 | AC23: =-LN(-LN(AB23)) -> 0.59170089 | AD23: ='Valeurs Maximales Annuelles'!J18 -> 60.713037 | AE23: =AD$5+AC23*AD$4 -> 70.462016 | AF23: =1/(1-AG23) -> 2.2222222 | AG23: 0.55 | AH23: =AD$5-AD$4*LN(-LN(AG23)) -> 68.459587 | AI23: =-LN(-LN(AG23)) -> 0.51443714 | AJ23: =AH23-AL23*1.96 -> 53.91625 | AK23: =AH23+AL23*1.96 -> 83.002924 | AL23: =(STDEV(AD$12:AD$1000)/SQRT(AD$8-1))*SQRT(0.7099+0.1165*AI23+0.6687*AI23*AI23) -> 7.4200699 | AN23: =RANK(AQ23,AQ$12:AQ$970,1) -> 12 | AO23: =(AN23-0.5)/COUNT(AN$12:AN$970) -> 0.575 | AP23: =-LN(-LN(AO23)) -> 0.59170089 | AQ23: ='Valeurs Maximales Annuelles'!L18 -> 64.341592 | AR23: =AQ$5+AP23*AQ$4 -> 76.729475 | AS23: =1/(1-AT23) -> 2.2222222 | AT23: 0.55 | AU23: =AQ$5-AQ$4*LN(-LN(AT23)) -> 74.107269 | AV23: =-LN(-LN(AT23)) -> 0.51443714 | AW23: =AU23-AY23*1.96 -> 55.062585 | AX23: =AU23+AY23*1.96 -> 93.151953 | AY23: =(STDEV(AQ$12:AQ$1000)/SQRT(AQ$8-1))*SQRT(0.7099+0.1165*AV23+0.6687*AV23*AV23) -> 9.7166755 | BA23: =RANK(BD23,BD$12:BD$970,1) -> 12 | BB23: =(BA23-0.5)/COUNT(BA$12:BA$970) -> 0.575 | BC23: =-LN(-LN(BB23)) -> 0.59170089 | BD23: ='Valeurs Maximales Annuelles'!N18 -> 69.16986 | BE23: =BD$5+BC23*BD$4 -> 77.772545 | BF23: =1/(1-BG23) -> 2.2222222 | BG23: 0.55 | BH23: =BD$5-BD$4*LN(-LN(BG23)) -> 75.298136 | BI23: =-LN(-LN(BG23)) -> 0.51443714 | BJ23: =BH23-BL23*1.96 -> 57.326883 | BK23: =BH23+BL23*1.96 -> 93.269389 | BL23: =(STDEV(BD$12:BD$1000)/SQRT(BD$8-1))*SQRT(0.7099+0.1165*BI23+0.6687*BI23*BI23) -> 9.1690068 | BN23: =RANK(BQ23,BQ$12:BQ$970,1) -> 12 | BO23: =(BN23-0.5)/COUNT(BN$12:BN$970) -> 0.575 | BP23: =-LN(-LN(BO23)) -> 0.59170089 | BQ23: ='Valeurs Maximales Annuelles'!P18 -> 64.768308 | BR23: =BQ$5+BP23*BQ$4 -> 76.685927 | BS23: =1/(1-BT23) -> 2.2222222 | BT23: 0.55 | BU23: =BQ$5-BQ$4*LN(-LN(BT23)) -> 74.088793 | BV23: =-LN(-LN(BT23)) -> 0.51443714 | BW23: =BU23-BY23*1.96 -> 55.226205 | BX23: =BU23+BY23*1.96 -> 92.951381 | BY23: =(STDEV(BQ$12:BQ$1000)/SQRT(BQ$8-1))*SQRT(0.7099+0.1165*BV23+0.6687*BV23*BV23) -> 9.6237696
... A31: =RANK(D31,D$12:D$970,1) -> 20 | B31: =(A31-0.5)/COUNT(A$12:A$970) -> 0.975 | C31: =-LN(-LN(B31)) -> 3.6762473 | D31: ='Valeurs Maximales Annuelles'!F26 -> 145.2444 | E31: =D$5+C31*D$4 -> 143.04656 | F31: =1/(1-G31) -> 20 | G31: 0.95 | H31: =D$5-D$4*LN(-LN(G31)) -> 125.81642 | I31: =-LN(-LN(G31)) -> 2.9701952 | J31: =H31-L31*1.96 -> 88.700399 | K31: =H31+L31*1.96 -> 162.93245 | L31: =(STDEV(D$12:D$1000)/SQRT(D$8-1))*SQRT(0.7099+0.1165*I31+0.6687*I31*I31) -> 18.936747 | N31: =RANK(Q31,Q$12:Q$970,1) -> 20 | O31: =(N31-0.5)/COUNT(N$12:N$970) -> 0.975 | P31: =-LN(-LN(O31)) -> 3.6762473 | Q31: ='Valeurs Maximales Annuelles'!H26 -> 180.25959 | R31: =Q$5+P31*Q$4 -> 175.40397 | S31: =1/(1-T31) -> 20 | T31: 0.95 | U31: =Q$5-Q$4*LN(-LN(T31)) -> 152.36426 | V31: =-LN(-LN(T31)) -> 2.9701952 | W31: =U31-Y31*1.96 -> 102.73361 | X31: =U31+Y31*1.96 -> 201.9949 | Y31: =(STDEV(Q$12:Q$1000)/SQRT(Q$8-1))*SQRT(0.7099+0.1165*V31+0.6687*V31*V31) -> 25.321756 | AA31: =RANK(AD31,AD$12:AD$970,1) -> 20 | AB31: =(AA31-0.5)/COUNT(AA$12:AA$970) -> 0.975 | AC31: =-LN(-LN(AB31)) -> 3.6762473 | AD31: ='Valeurs Maximales Annuelles'!J26 -> 148.15862 | AE31: =AD$5+AC31*AD$4 -> 150.40358 | AF31: =1/(1-AG31) -> 20 | AG31: 0.95 | AH31: =AD$5-AD$4*LN(-LN(AG31)) -> 132.10497 | AI31: =-LN(-LN(AG31)) -> 2.9701952 | AJ31: =AH31-AL31*1.96 -> 92.687308 | AK31: =AH31+AL31*1.96 -> 171.52264 | AL31: =(STDEV(AD$12:AD$1000)/SQRT(AD$8-1))*SQRT(0.7099+0.1165*AI31+0.6687*AI31*AI31) -> 20.111053 | AN31: =RANK(AQ31,AQ$12:AQ$970,1) -> 20 | AO31: =(AN31-0.5)/COUNT(AN$12:AN$970) -> 0.975 | AP31: =-LN(-LN(AO31)) -> 3.6762473 | AQ31: ='Valeurs Maximales Annuelles'!L26 -> 178.83379 | AR31: =AQ$5+AP31*AQ$4 -> 181.41396 | AS31: =1/(1-AT31) -> 20 | AT31: 0.95 | AU31: =AQ$5-AQ$4*LN(-LN(AT31)) -> 157.45171 | AV31: =-LN(-LN(AT31)) -> 2.9701952 | AW31: =AU31-AY31*1.96 -> 105.83378 | AX31: =AU31+AY31*1.96 -> 209.06964 | AY31: =(STDEV(AQ$12:AQ$1000)/SQRT(AQ$8-1))*SQRT(0.7099+0.1165*AV31+0.6687*AV31*AV31) -> 26.335679 | BA31: =RANK(BD31,BD$12:BD$970,1) -> 20 | BB31: =(BA31-0.5)/COUNT(BA$12:BA$970) -> 0.975 | BC31: =-LN(-LN(BB31)) -> 3.6762473 | BD31: ='Valeurs Maximales Annuelles'!N26 -> 180.25959 | BE31: =BD$5+BC31*BD$4 -> 176.55662 | BF31: =1/(1-BG31) -> 20 | BG31: 0.95 | BH31: =BD$5-BD$4*LN(-LN(BG31)) -> 153.94496 | BI31: =-LN(-LN(BG31)) -> 2.9701952 | BJ31: =BH31-BL31*1.96 -> 105.23642 | BK31: =BH31+BL31*1.96 -> 202.65351 | BL31: =(STDEV(BD$12:BD$1000)/SQRT(BD$8-1))*SQRT(0.7099+0.1165*BI31+0.6687*BI31*BI31) -> 24.8513 | BN31: =RANK(BQ31,BQ$12:BQ$970,1) -> 20 | BO31: =(BN31-0.5)/COUNT(BN$12:BN$970) -> 0.975 | BP31: =-LN(-LN(BO31)) -> 3.6762473 | BQ31: ='Valeurs Maximales Annuelles'!P26 -> 180.25959 | BR31: =BQ$5+BP31*BQ$4 -> 180.36948 | BS31: =1/(1-BT31) -> 20 | BT31: 0.95 | BU31: =BQ$5-BQ$4*LN(-LN(BT31)) -> 156.63633 | BV31: =-LN(-LN(BT31)) -> 2.9701952 | BW31: =BU31-BY31*1.96 -> 105.51195 | BX31: =BU31+BY31*1.96 -> 207.76072 | BY31: =(STDEV(BQ$12:BQ$1000)/SQRT(BQ$8-1))*SQRT(0.7099+0.1165*BV31+0.6687*BV31*BV31) -> 26.08387
A32: =RANK(D32,D$12:D$970,1) -> #N/A | E32: =D$5+C32*D$4 -> 53.3333 | F32: =1/(1-G32) -> 29.9994 | G32: 0.966666 | H32: =D$5-D$4*LN(-LN(G32)) -> 135.92139 | I32: =-LN(-LN(G32)) -> 3.3842742 | J32: =H32-L32*1.96 -> 94.260195 | K32: =H32+L32*1.96 -> 177.58259 | L32: =(STDEV(D$12:D$1000)/SQRT(D$8-1))*SQRT(0.7099+0.1165*I32+0.6687*I32*I32) -> 21.255714 | N32: =RANK(Q32,Q$12:Q$970,1) -> #N/A | R32: =Q$5+P32*Q$4 -> 55.441591 | S32: =1/(1-T32) -> 29.9994 | T32: 0.966666 | U32: =Q$5-Q$4*LN(-LN(T32)) -> 165.87637 | V32: =-LN(-LN(T32)) -> 3.3842742 | W32: =U32-Y32*1.96 -> 110.16804 | X32: =U32+Y32*1.96 -> 221.58471 | Y32: =(STDEV(Q$12:Q$1000)/SQRT(Q$8-1))*SQRT(0.7099+0.1165*V32+0.6687*V32*V32) -> 28.422622 | AE32: =AD$5+AC32*AD$4 -> 55.127024 | AF32: =1/(1-AG32) -> 29.9994 | AG32: 0.966666 | AH32: =AD$5-AD$4*LN(-LN(AG32)) -> 142.83657 | AI32: =-LN(-LN(AG32)) -> 3.3842742 | AJ32: =AH32-AL32*1.96 -> 98.591878 | AK32: =AH32+AL32*1.96 -> 187.08126 | AL32: =(STDEV(AD$12:AD$1000)/SQRT(AD$8-1))*SQRT(0.7099+0.1165*AI32+0.6687*AI32*AI32) -> 22.573823 | AR32: =AQ$5+AP32*AQ$4 -> 56.648109 | AS32: =1/(1-AT32) -> 29.9994 | AT32: 0.966666 | AU32: =AQ$5-AQ$4*LN(-LN(AT32)) -> 171.50487 | AV32: =-LN(-LN(AT32)) -> 3.3842742 | AW32: =AU32-AY32*1.96 -> 113.56588 | AX32: =AU32+AY32*1.96 -> 229.44386 | AY32: =(STDEV(AQ$12:AQ$1000)/SQRT(AQ$8-1))*SQRT(0.7099+0.1165*AV32+0.6687*AV32*AV32) -> 29.560707 | BE32: =BD$5+BC32*BD$4 -> 58.823041 | BF32: =1/(1-BG32) -> 29.9994 | BG32: 0.966666 | BH32: =BD$5-BD$4*LN(-LN(BG32)) -> 167.20604 | BI32: =-LN(-LN(BG32)) -> 3.3842742 | BJ32: =BH32-BL32*1.96 -> 112.53271 | BK32: =BH32+BL32*1.96 -> 221.87936 | BL32: =(STDEV(BD$12:BD$1000)/SQRT(BD$8-1))*SQRT(0.7099+0.1165*BI32+0.6687*BI32*BI32) -> 27.894554 | BR32: =BQ$5+BP32*BQ$4 -> 56.796569 | BS32: =1/(1-BT32) -> 29.9994 | BT32: 0.966666 | BU32: =BQ$5-BQ$4*LN(-LN(BT32)) -> 170.55513 | BV32: =-LN(-LN(BT32)) -> 3.3842742 | BW32: =BU32-BY32*1.96 -> 113.17013 | BX32: =BU32+BY32*1.96 -> 227.94013 | BY32: =(STDEV(BQ$12:BQ$1000)/SQRT(BQ$8-1))*SQRT(0.7099+0.1165*BV32+0.6687*BV32*BV32) -> 29.278063
A33: =RANK(D33,D$12:D$970,1) -> #N/A | E33: =D$5+C33*D$4 -> 53.3333 | F33: =1/(1-G33) -> 50 | G33: 0.98 | H33: =D$5-D$4*LN(-LN(G33)) -> 148.55421 | I33: =-LN(-LN(G33)) -> 3.9019387 | J33: =H33-L33*1.96 -> 101.14993 | K33: =H33+L33*1.96 -> 195.95849 | L33: =(STDEV(D$12:D$1000)/SQRT(D$8-1))*SQRT(0.7099+0.1165*I33+0.6687*I33*I33) -> 24.185858 | N33: =RANK(Q33,Q$12:Q$970,1) -> #N/A | R33: =Q$5+P33*Q$4 -> 55.441591 | S33: =1/(1-T33) -> 50 | T33: 0.98 | U33: =Q$5-Q$4*LN(-LN(T33)) -> 182.76867 | V33: =-LN(-LN(T33)) -> 3.9019387 | W33: =U33-Y33*1.96 -> 119.38082 | X33: =U33+Y33*1.96 -> 246.15652 | Y33: =(STDEV(Q$12:Q$1000)/SQRT(Q$8-1))*SQRT(0.7099+0.1165*V33+0.6687*V33*V33) -> 32.340739 | AE33: =AD$5+AC33*AD$4 -> 55.127024 | AF33: =1/(1-AG33) -> 50 | AG33: 0.98 | AH33: =AD$5-AD$4*LN(-LN(AG33)) -> 156.25278 | AI33: =-LN(-LN(AG33)) -> 3.9019387 | AJ33: =AH33-AL33*1.96 -> 105.90886 | AK33: =AH33+AL33*1.96 -> 206.59669 | AL33: =(STDEV(AD$12:AD$1000)/SQRT(AD$8-1))*SQRT(0.7099+0.1165*AI33+0.6687*AI33*AI33) -> 25.685672 | AR33: =AQ$5+AP33*AQ$4 -> 56.648109 | AS33: =1/(1-AT33) -> 50 | AT33: 0.98 | AU33: =AQ$5-AQ$4*LN(-LN(AT33)) -> 189.07356 | AV33: =-LN(-LN(AT33)) -> 3.9019387 | AW33: =AU33-AY33*1.96 -> 123.14757 | AX33: =AU33+AY33*1.96 -> 254.99956 | AY33: =(STDEV(AQ$12:AQ$1000)/SQRT(AQ$8-1))*SQRT(0.7099+0.1165*AV33+0.6687*AV33*AV33) -> 33.635712 | BE33: =BD$5+BC33*BD$4 -> 58.823041 | BF33: =1/(1-BG33) -> 50 | BG33: 0.98 | BH33: =BD$5-BD$4*LN(-LN(BG33)) -> 183.78449 | BI33: =-LN(-LN(BG33)) -> 3.9019387 | BJ33: =BH33-BL33*1.96 -> 121.57434 | BK33: =BH33+BL33*1.96 -> 245.99465 | BL33: =(STDEV(BD$12:BD$1000)/SQRT(BD$8-1))*SQRT(0.7099+0.1165*BI33+0.6687*BI33*BI33) -> 31.739876 | BR33: =BQ$5+BP33*BQ$4 -> 56.796569 | BS33: =1/(1-BT33) -> 50 | BT33: 0.98 | BU33: =BQ$5-BQ$4*LN(-LN(BT33)) -> 187.95584 | BV33: =-LN(-LN(BT33)) -> 3.9019387 | BW33: =BU33-BY33*1.96 -> 122.66019 | BX33: =BU33+BY33*1.96 -> 253.25148 | BY33: =(STDEV(BQ$12:BQ$1000)/SQRT(BQ$8-1))*SQRT(0.7099+0.1165*BV33+0.6687*BV33*BV33) -> 33.314105
A34: =RANK(D34,D$12:D$970,1) -> #N/A | E34: =D$5+C34*D$4 -> 53.3333 | F34: =1/(1-G34) -> 100 | G34: 0.99 | H34: =D$5-D$4*LN(-LN(G34)) -> 165.59299 | I34: =-LN(-LN(G34)) -> 4.6001492 | J34: =H34-L34*1.96 -> 110.37057 | K34: =H34+L34*1.96 -> 220.8154 | L34: =(STDEV(D$12:D$1000)/SQRT(D$8-1))*SQRT(0.7099+0.1165*I34+0.6687*I34*I34) -> 28.174702 | N34: =RANK(Q34,Q$12:Q$970,1) -> #N/A | R34: =Q$5+P34*Q$4 -> 55.441591 | S34: =1/(1-T34) -> 100 | T34: 0.99 | U34: =Q$5-Q$4*LN(-LN(T34)) -> 205.5525 | V34: =-LN(-LN(T34)) -> 4.6001492 | W34: =U34-Y34*1.96 -> 131.71044 | X34: =U34+Y34*1.96 -> 279.39457 | Y34: =(STDEV(Q$12:Q$1000)/SQRT(Q$8-1))*SQRT(0.7099+0.1165*V34+0.6687*V34*V34) -> 37.674524 | AE34: =AD$5+AC34*AD$4 -> 55.127024 | AF34: =1/(1-AG34) -> 100 | AG34: 0.99 | AH34: =AD$5-AD$4*LN(-LN(AG34)) -> 174.34816 | AI34: =-LN(-LN(AG34)) -> 4.6001492 | AJ34: =AH34-AL34*1.96 -> 115.70129 | AK34: =AH34+AL34*1.96 -> 232.99503 | AL34: =(STDEV(AD$12:AD$1000)/SQRT(AD$8-1))*SQRT(0.7099+0.1165*AI34+0.6687*AI34*AI34) -> 29.921872 | AR34: =AQ$5+AP34*AQ$4 -> 56.648109 | AS34: =1/(1-AT34) -> 100 | AT34: 0.99 | AU34: =AQ$5-AQ$4*LN(-LN(AT34)) -> 212.76969 | AV34: =-LN(-LN(AT34)) -> 4.6001492 | AW34: =AU34-AY34*1.96 -> 135.97088 | AX34: =AU34+AY34*1.96 -> 289.56851 | AY34: =(STDEV(AQ$12:AQ$1000)/SQRT(AQ$8-1))*SQRT(0.7099+0.1165*AV34+0.6687*AV34*AV34) -> 39.18307 | BE34: =BD$5+BC34*BD$4 -> 58.823041 | BF34: =1/(1-BG34) -> 100 | BG34: 0.99 | BH34: =BD$5-BD$4*LN(-LN(BG34)) -> 206.14502 | BI34: =-LN(-LN(BG34)) -> 4.6001492 | BJ34: =BH34-BL34*1.96 -> 133.67488 | BK34: =BH34+BL34*1.96 -> 278.61516 | BL34: =(STDEV(BD$12:BD$1000)/SQRT(BD$8-1))*SQRT(0.7099+0.1165*BI34+0.6687*BI34*BI34) -> 36.974563 | BR34: =BQ$5+BP34*BQ$4 -> 56.796569 | BS34: =1/(1-BT34) -> 100 | BT34: 0.99 | BU34: =BQ$5-BQ$4*LN(-LN(BT34)) -> 211.4254 | BV34: =-LN(-LN(BT34)) -> 4.6001492 | BW34: =BU34-BY34*1.96 -> 135.36089 | BX34: =BU34+BY34*1.96 -> 287.4899 | BY34: =(STDEV(BQ$12:BQ$1000)/SQRT(BQ$8-1))*SQRT(0.7099+0.1165*BV34+0.6687*BV34*BV34) -> 38.808421
